<?xml version="1.0" ?>
<!-- =================================================================================== -->
<!-- |    This document was autogenerated by xacro from /home/yaqub/yaqub_ws/src/px4_simulation_stack-master/Tools/sitl_gazebo/models/F550_rd/F550_rd.xacro | -->
<!-- |    EDITING THIS FILE BY HAND IS NOT RECOMMENDED                                 | -->
<!-- =================================================================================== -->
<robot name="F550_rd" xmlns:xacro="http://www.ros.org/wiki/xacro">
  <link name="base_link"/>
  <joint name="base_joint" type="fixed">
    <origin rpy="0 0 0" xyz="0 0 0"/>
    <parent link="base_link"/>
    <child link="base_link_inertia"/>
  </joint>
  <!-- base_link -->
  <link name="base_link_inertia">
    <inertial>
      <mass value="1.5"/>
      <!-- [kg] -->
      <origin xyz="0 0 0"/>
      <inertia ixx="0.00012113" ixy="-2.4623E-08" ixz="1.6419E-06" iyy="0.00013125" iyz="6.0617E-07" izz="1.8253E-05"/>
    </inertial>
    <visual>
      <origin rpy="0 0 0" xyz="0 0 0"/>
      <geometry>
        <mesh filename="model://F550/meshes/base_link.STL" scale="1 1 1"/>
      </geometry>
    </visual>
    <collision>
      <origin rpy="0 0 0" xyz="0 0 0.03"/>
      <geometry>
        <cylinder length="0.13" radius="0.295"/>
      </geometry>
    </collision>
  </link>
  <gazebo>
    <plugin filename="libgazebo_multirotor_base_plugin.so" name="rosbag">
      <robotNamespace></robotNamespace>
      <linkName>base_link</linkName>
      <rotorVelocitySlowdownSim>10</rotorVelocitySlowdownSim>
    </plugin>
  </gazebo>
  <gazebo reference="base_link">
    <material>Gazebo/Black</material>
    <collision name="base_link_inertia_collision">
      <surface>
        <contact>
          <ode>
            <min_depth>0.001</min_depth>
            <max_vel>0.0</max_vel>
          </ode>
        </contact>
        <friction>
          <ode/>
        </friction>
      </surface>
    </collision>
  </gazebo>
  <!-- wing joint -->
  <joint name="wing_0_joint" type="fixed">
    <origin rpy="0 0 -1.57079632679" xyz="0 -0.1875 0.026"/>
    <axis xyz="0 0 0"/>
    <parent link="base_link"/>
    <child link="wing_0"/>
  </joint>
  <!-- wing link -->
  <link name="wing_0">
    <inertial>
      <origin rpy="0 0 0" xyz="0.033233 0.00054387 0.012567"/>
      <mass value="0.11819"/>
      <inertia ixx="2.1906E-05" ixy="7.962E-07" ixz="-6.9968E-05" iyy="0.0002878" iyz="2.0567E-07" izz="0.0002659"/>
    </inertial>
    <visual>
      <geometry>
        <mesh filename="model://F550/meshes/wing.STL" scale="1 1 1"/>
      </geometry>
    </visual>
  </link>
  <gazebo reference="wing_0">
    <material>Gazebo/White</material>
  </gazebo>
  <!-- rotor joint -->
  <joint name="rotor_0_joint" type="continuous">
    <origin rpy="0 0 0" xyz="0.0865 0.0005 0.033"/>
    <axis xyz="0 0 1"/>
    <parent link="wing_0"/>
    <child link="rotor_0"/>
  </joint>
  <!-- rotor link -->
  <link name="rotor_0">
    <inertial>
      <origin rpy="0 0 0" xyz="0 0 0.0078525"/>
      <mass value="0.0091837"/>
      <inertia ixx="3.009E-07" ixy="1.5042E-07" ixz="0" iyy="3.4024E-05" iyz="0" izz="3.4239E-05"/>
    </inertial>
    <visual>
      <geometry>
        <mesh filename="model://F550/meshes/cw_prop.STL" scale="1 1 1"/>
      </geometry>
    </visual>
    <collision>
      <geometry>
        <cylinder length="0.03" radius="0.13"/>
      </geometry>
    </collision>
  </link>
  <gazebo>
    <plugin filename="libgazebo_motor_model.so" name="right_motor_model">
      <robotNamespace></robotNamespace>
      <jointName>rotor_0_joint</jointName>
      <linkName>rotor_0</linkName>
      <turningDirection>cw</turningDirection>
      <timeConstantUp>0.0125</timeConstantUp>
      <timeConstantDown>0.025</timeConstantDown>
      <maxRotVelocity>1500</maxRotVelocity>
      <motorConstant>8.54858e-06</motorConstant>
      <momentConstant>0.06</momentConstant>
      <commandSubTopic>/gazebo/command/motor_speed</commandSubTopic>
      <motorNumber>0</motorNumber>
      <rotorDragCoefficient>0.000806428</rotorDragCoefficient>
      <rollingMomentCoefficient>1e-06</rollingMomentCoefficient>
      <motorSpeedPubTopic>/motor_speed/0</motorSpeedPubTopic>
      <rotorVelocitySlowdownSim>10</rotorVelocitySlowdownSim>
    </plugin>
  </gazebo>
  <gazebo reference="rotor_0">
    <material>Gazebo/Black</material>
  </gazebo>
  <!-- wing joint -->
  <joint name="wing_1_joint" type="fixed">
    <origin rpy="0 0 1.57079632679" xyz="0 0.1875 0.026"/>
    <axis xyz="0 0 0"/>
    <parent link="base_link"/>
    <child link="wing_1"/>
  </joint>
  <!-- wing link -->
  <link name="wing_1">
    <inertial>
      <origin rpy="0 0 0" xyz="0.033233 0.00054387 0.012567"/>
      <mass value="0.11819"/>
      <inertia ixx="2.1906E-05" ixy="7.962E-07" ixz="-6.9968E-05" iyy="0.0002878" iyz="2.0567E-07" izz="0.0002659"/>
    </inertial>
    <visual>
      <geometry>
        <mesh filename="model://F550/meshes/wing.STL" scale="1 1 1"/>
      </geometry>
    </visual>
  </link>
  <gazebo reference="wing_1">
    <material>Gazebo/White</material>
  </gazebo>
  <!-- rotor joint -->
  <joint name="rotor_1_joint" type="continuous">
    <origin rpy="0 0 0" xyz="0.0865 0.0005 0.033"/>
    <axis xyz="0 0 1"/>
    <parent link="wing_1"/>
    <child link="rotor_1"/>
  </joint>
  <!-- rotor link -->
  <link name="rotor_1">
    <inertial>
      <origin rpy="0 0 0" xyz="0 0 0.0078525"/>
      <mass value="0.0091837"/>
      <inertia ixx="3.00752E-07" ixy="-1.4455E-07" ixz="0" iyy="3.41061E-05" iyz="0" izz="3.43204E-05"/>
    </inertial>
    <visual>
      <geometry>
        <mesh filename="model://F550/meshes/ccw_prop.STL" scale="1 1 1"/>
      </geometry>
    </visual>
    <collision>
      <geometry>
        <cylinder length="0.03" radius="0.13"/>
      </geometry>
    </collision>
  </link>
  <gazebo>
    <plugin filename="libgazebo_motor_model.so" name="left_motor_model">
      <robotNamespace></robotNamespace>
      <jointName>rotor_1_joint</jointName>
      <linkName>rotor_1</linkName>
      <turningDirection>ccw</turningDirection>
      <timeConstantUp>0.0125</timeConstantUp>
      <timeConstantDown>0.025</timeConstantDown>
      <maxRotVelocity>1500</maxRotVelocity>
      <motorConstant>8.54858e-06</motorConstant>
      <momentConstant>0.06</momentConstant>
      <commandSubTopic>/gazebo/command/motor_speed</commandSubTopic>
      <motorNumber>1</motorNumber>
      <rotorDragCoefficient>0.000806428</rotorDragCoefficient>
      <rollingMomentCoefficient>1e-06</rollingMomentCoefficient>
      <motorSpeedPubTopic>/motor_speed/1</motorSpeedPubTopic>
      <rotorVelocitySlowdownSim>10</rotorVelocitySlowdownSim>
    </plugin>
  </gazebo>
  <gazebo reference="rotor_1">
    <material>Gazebo/Orange</material>
  </gazebo>
  <!-- wing joint -->
  <joint name="wing_2_joint" type="fixed">
    <origin rpy="0 0 0.523598775598" xyz="0.16237976321 0.09375 0.026"/>
    <axis xyz="0 0 0"/>
    <parent link="base_link"/>
    <child link="wing_2"/>
  </joint>
  <!-- wing link -->
  <link name="wing_2">
    <inertial>
      <origin rpy="0 0 0" xyz="0.033233 0.00054387 0.012567"/>
      <mass value="0.11819"/>
      <inertia ixx="2.1906E-05" ixy="7.962E-07" ixz="-6.9968E-05" iyy="0.0002878" iyz="2.0567E-07" izz="0.0002659"/>
    </inertial>
    <visual>
      <geometry>
        <mesh filename="model://F550/meshes/wing.STL" scale="1 1 1"/>
      </geometry>
    </visual>
  </link>
  <gazebo reference="wing_2">
    <material>Gazebo/White</material>
  </gazebo>
  <!-- rotor joint -->
  <joint name="rotor_2_joint" type="continuous">
    <origin rpy="0 0 0" xyz="0.0865 0.0005 0.033"/>
    <axis xyz="0 0 1"/>
    <parent link="wing_2"/>
    <child link="rotor_2"/>
  </joint>
  <!-- rotor link -->
  <link name="rotor_2">
    <inertial>
      <origin rpy="0 0 0" xyz="0 0 0.0078525"/>
      <mass value="0.0091837"/>
      <inertia ixx="3.009E-07" ixy="1.5042E-07" ixz="0" iyy="3.4024E-05" iyz="0" izz="3.4239E-05"/>
    </inertial>
    <visual>
      <geometry>
        <mesh filename="model://F550/meshes/cw_prop.STL" scale="1 1 1"/>
      </geometry>
    </visual>
    <collision>
      <geometry>
        <cylinder length="0.03" radius="0.13"/>
      </geometry>
    </collision>
  </link>
  <gazebo>
    <plugin filename="libgazebo_motor_model.so" name="left_front_motor_model">
      <robotNamespace></robotNamespace>
      <jointName>rotor_2_joint</jointName>
      <linkName>rotor_2</linkName>
      <turningDirection>cw</turningDirection>
      <timeConstantUp>0.0125</timeConstantUp>
      <timeConstantDown>0.025</timeConstantDown>
      <maxRotVelocity>1500</maxRotVelocity>
      <motorConstant>8.54858e-06</motorConstant>
      <momentConstant>0.06</momentConstant>
      <commandSubTopic>/gazebo/command/motor_speed</commandSubTopic>
      <motorNumber>2</motorNumber>
      <rotorDragCoefficient>0.000806428</rotorDragCoefficient>
      <rollingMomentCoefficient>1e-06</rollingMomentCoefficient>
      <motorSpeedPubTopic>/motor_speed/2</motorSpeedPubTopic>
      <rotorVelocitySlowdownSim>10</rotorVelocitySlowdownSim>
    </plugin>
  </gazebo>
  <gazebo reference="rotor_2">
    <material>Gazebo/Black</material>
  </gazebo>
  <!-- wing joint -->
  <joint name="wing_3_joint" type="fixed">
    <origin rpy="0 0 -2.61799387799" xyz="-0.16237976321 -0.09375 0.026"/>
    <axis xyz="0 0 0"/>
    <parent link="base_link"/>
    <child link="wing_3"/>
  </joint>
  <!-- wing link -->
  <link name="wing_3">
    <inertial>
      <origin rpy="0 0 0" xyz="0.033233 0.00054387 0.012567"/>
      <mass value="0.11819"/>
      <inertia ixx="2.1906E-05" ixy="7.962E-07" ixz="-6.9968E-05" iyy="0.0002878" iyz="2.0567E-07" izz="0.0002659"/>
    </inertial>
    <visual>
      <geometry>
        <mesh filename="model://F550/meshes/wing.STL" scale="1 1 1"/>
      </geometry>
    </visual>
  </link>
  <gazebo reference="wing_3">
    <material>Gazebo/Red</material>
  </gazebo>
  <!-- rotor joint -->
  <joint name="rotor_3_joint" type="continuous">
    <origin rpy="0 0 0" xyz="0.0865 0.0005 0.033"/>
    <axis xyz="0 0 1"/>
    <parent link="wing_3"/>
    <child link="rotor_3"/>
  </joint>
  <!-- rotor link -->
  <link name="rotor_3">
    <inertial>
      <origin rpy="0 0 0" xyz="0 0 0.0078525"/>
      <mass value="0.0091837"/>
      <inertia ixx="3.00752E-07" ixy="-1.4455E-07" ixz="0" iyy="3.41061E-05" iyz="0" izz="3.43204E-05"/>
    </inertial>
    <visual>
      <geometry>
        <mesh filename="model://F550/meshes/ccw_prop.STL" scale="1 1 1"/>
      </geometry>
    </visual>
    <collision>
      <geometry>
        <cylinder length="0.03" radius="0.13"/>
      </geometry>
    </collision>
  </link>
  <gazebo>
    <plugin filename="libgazebo_motor_model.so" name="right_rear_motor_model">
      <robotNamespace></robotNamespace>
      <jointName>rotor_3_joint</jointName>
      <linkName>rotor_3</linkName>
      <turningDirection>ccw</turningDirection>
      <timeConstantUp>0.0125</timeConstantUp>
      <timeConstantDown>0.025</timeConstantDown>
      <maxRotVelocity>1500</maxRotVelocity>
      <motorConstant>8.54858e-06</motorConstant>
      <momentConstant>0.06</momentConstant>
      <commandSubTopic>/gazebo/command/motor_speed</commandSubTopic>
      <motorNumber>3</motorNumber>
      <rotorDragCoefficient>0.000806428</rotorDragCoefficient>
      <rollingMomentCoefficient>1e-06</rollingMomentCoefficient>
      <motorSpeedPubTopic>/motor_speed/3</motorSpeedPubTopic>
      <rotorVelocitySlowdownSim>10</rotorVelocitySlowdownSim>
    </plugin>
  </gazebo>
  <gazebo reference="rotor_3">
    <material>Gazebo/Orange</material>
  </gazebo>
  <!-- wing joint -->
  <joint name="wing_4_joint" type="fixed">
    <origin rpy="0 0 -0.523598775598" xyz="0.16237976321 -0.09375 0.026"/>
    <axis xyz="0 0 0"/>
    <parent link="base_link"/>
    <child link="wing_4"/>
  </joint>
  <!-- wing link -->
  <link name="wing_4">
    <inertial>
      <origin rpy="0 0 0" xyz="0.033233 0.00054387 0.012567"/>
      <mass value="0.11819"/>
      <inertia ixx="2.1906E-05" ixy="7.962E-07" ixz="-6.9968E-05" iyy="0.0002878" iyz="2.0567E-07" izz="0.0002659"/>
    </inertial>
    <visual>
      <geometry>
        <mesh filename="model://F550/meshes/wing.STL" scale="1 1 1"/>
      </geometry>
    </visual>
  </link>
  <gazebo reference="wing_4">
    <material>Gazebo/White</material>
  </gazebo>
  <!-- rotor joint -->
  <joint name="rotor_4_joint" type="continuous">
    <origin rpy="0 0 0" xyz="0.0865 0.0005 0.033"/>
    <axis xyz="0 0 1"/>
    <parent link="wing_4"/>
    <child link="rotor_4"/>
  </joint>
  <!-- rotor link -->
  <link name="rotor_4">
    <inertial>
      <origin rpy="0 0 0" xyz="0 0 0.0078525"/>
      <mass value="0.0091837"/>
      <inertia ixx="3.00752E-07" ixy="-1.4455E-07" ixz="0" iyy="3.41061E-05" iyz="0" izz="3.43204E-05"/>
    </inertial>
    <visual>
      <geometry>
        <mesh filename="model://F550/meshes/ccw_prop.STL" scale="1 1 1"/>
      </geometry>
    </visual>
    <collision>
      <geometry>
        <cylinder length="0.03" radius="0.13"/>
      </geometry>
    </collision>
  </link>
  <gazebo>
    <plugin filename="libgazebo_motor_model.so" name="right_front_motor_model">
      <robotNamespace></robotNamespace>
      <jointName>rotor_4_joint</jointName>
      <linkName>rotor_4</linkName>
      <turningDirection>ccw</turningDirection>
      <timeConstantUp>0.0125</timeConstantUp>
      <timeConstantDown>0.025</timeConstantDown>
      <maxRotVelocity>1500</maxRotVelocity>
      <motorConstant>8.54858e-06</motorConstant>
      <momentConstant>0.06</momentConstant>
      <commandSubTopic>/gazebo/command/motor_speed</commandSubTopic>
      <motorNumber>4</motorNumber>
      <rotorDragCoefficient>0.000806428</rotorDragCoefficient>
      <rollingMomentCoefficient>1e-06</rollingMomentCoefficient>
      <motorSpeedPubTopic>/motor_speed/4</motorSpeedPubTopic>
      <rotorVelocitySlowdownSim>10</rotorVelocitySlowdownSim>
    </plugin>
  </gazebo>
  <gazebo reference="rotor_4">
    <material>Gazebo/Orange</material>
  </gazebo>
  <!-- wing joint -->
  <joint name="wing_5_joint" type="fixed">
    <origin rpy="0 0 2.61799387799" xyz="-0.16237976321 0.09375 0.026"/>
    <axis xyz="0 0 0"/>
    <parent link="base_link"/>
    <child link="wing_5"/>
  </joint>
  <!-- wing link -->
  <link name="wing_5">
    <inertial>
      <origin rpy="0 0 0" xyz="0.033233 0.00054387 0.012567"/>
      <mass value="0.11819"/>
      <inertia ixx="2.1906E-05" ixy="7.962E-07" ixz="-6.9968E-05" iyy="0.0002878" iyz="2.0567E-07" izz="0.0002659"/>
    </inertial>
    <visual>
      <geometry>
        <mesh filename="model://F550/meshes/wing.STL" scale="1 1 1"/>
      </geometry>
    </visual>
  </link>
  <gazebo reference="wing_5">
    <material>Gazebo/Red</material>
  </gazebo>
  <!-- rotor joint -->
  <joint name="rotor_5_joint" type="continuous">
    <origin rpy="0 0 0" xyz="0.0865 0.0005 0.033"/>
    <axis xyz="0 0 1"/>
    <parent link="wing_5"/>
    <child link="rotor_5"/>
  </joint>
  <!-- rotor link -->
  <link name="rotor_5">
    <inertial>
      <origin rpy="0 0 0" xyz="0 0 0.0078525"/>
      <mass value="0.0091837"/>
      <inertia ixx="3.009E-07" ixy="1.5042E-07" ixz="0" iyy="3.4024E-05" iyz="0" izz="3.4239E-05"/>
    </inertial>
    <visual>
      <geometry>
        <mesh filename="model://F550/meshes/cw_prop.STL" scale="1 1 1"/>
      </geometry>
    </visual>
    <collision>
      <geometry>
        <cylinder length="0.03" radius="0.13"/>
      </geometry>
    </collision>
  </link>
  <gazebo>
    <plugin filename="libgazebo_motor_model.so" name="left_rear_motor_model">
      <robotNamespace></robotNamespace>
      <jointName>rotor_5_joint</jointName>
      <linkName>rotor_5</linkName>
      <turningDirection>cw</turningDirection>
      <timeConstantUp>0.0125</timeConstantUp>
      <timeConstantDown>0.025</timeConstantDown>
      <maxRotVelocity>1500</maxRotVelocity>
      <motorConstant>8.54858e-06</motorConstant>
      <momentConstant>0.06</momentConstant>
      <commandSubTopic>/gazebo/command/motor_speed</commandSubTopic>
      <motorNumber>5</motorNumber>
      <rotorDragCoefficient>0.000806428</rotorDragCoefficient>
      <rollingMomentCoefficient>1e-06</rollingMomentCoefficient>
      <motorSpeedPubTopic>/motor_speed/5</motorSpeedPubTopic>
      <rotorVelocitySlowdownSim>10</rotorVelocitySlowdownSim>
    </plugin>
  </gazebo>
  <gazebo reference="rotor_5">
    <material>Gazebo/Black</material>
  </gazebo>
  <!-- link -->
  <link name="pixhawk">
    <inertial>
      <origin rpy="0 0 0" xyz="-0.0024647 9.4432E-05 0.011865"/>
      <mass value="0.074008"/>
      <inertia ixx="3.8198E-06" ixy="-6.11E-09" ixz="2.3562E-07" iyy="3.8099E-06" iyz="7.5702E-08" izz="4.7645E-08"/>
    </inertial>
    <visual>
      <geometry>
        <mesh filename="model://F550/meshes/pixhawk.STL" scale="1 1 1"/>
      </geometry>
    </visual>
  </link>
  <gazebo reference="pixhawk">
    <material>Gazebo/FlatBlack</material>
  </gazebo>
  <!-- joint -->
  <joint name="pixhawk_fix" type="fixed">
    <origin rpy="0 0 0" xyz="0 0 0"/>
    <parent link="base_link"/>
    <child link="pixhawk"/>
    <axis xyz="0 0 0"/>
  </joint>
  <!-- link -->
  <link name="here_gps">
    <inertial>
      <origin rpy="0 0 0" xyz="-6.68E-05 -0.0084082 1.31210000000051E-06"/>
      <mass value="0.045664"/>
      <inertia ixx="1.18897973921917E-05" ixy="1.90905250559444E-08" ixz="-4.16447287511186E-11" iyy="2.23807703040404E-05" iyz="2.02155100330627E-11" izz="1.19471291213534E-05"/>
    </inertial>
    <visual>
      <geometry>
        <mesh filename="model://F550/meshes/here_gps.STL" scale="1 1 1"/>
      </geometry>
    </visual>
  </link>
  <gazebo reference="here_gps">
    <material>Gazebo/DarkGrey</material>
  </gazebo>
  <!-- joint -->
  <joint name="here_gps_fix" type="fixed">
    <origin rpy="0 0 0" xyz="0 -0.09 0.20"/>
    <parent link="base_link"/>
    <child link="here_gps"/>
    <axis xyz="0 0 0"/>
  </joint>
  <!-- GPS Holder -->
  <!-- link -->
  <link name="gps_holder">
    <visual>
      <geometry>
        <cylinder length="0.165" radius="0.002"/>
      </geometry>
    </visual>
  </link>
  <gazebo reference="gps_holder">
    <material>Gazebo/DarkGrey</material>
  </gazebo>
  <!-- joint -->
  <joint name="gps_holder_fix" type="fixed">
    <origin rpy="0 0 0" xyz="0 -0.09 0.122"/>
    <parent link="base_link"/>
    <child link="gps_holder"/>
  </joint>
  <gazebo>
    <plugin filename="libgazebo_gps_plugin.so" name="gps_plugin">
      <robotNamespace></robotNamespace>
      <gpsNoise>true</gpsNoise>
    </plugin>
  </gazebo>
  <gazebo>
    <plugin filename="libgazebo_mavlink_interface.so" name="mavlink_interface">
      <robotNamespace></robotNamespace>
      <imuSubTopic>/imu</imuSubTopic>
      <gpsSubTopic>/gps</gpsSubTopic>
      <mavlink_addr>INADDR_ANY</mavlink_addr>
      <mavlink_udp_port>14560</mavlink_udp_port>
      <serialEnabled>false</serialEnabled>
      <serialDevice>/dev/ttyACM0</serialDevice>
      <baudRate>57600</baudRate>
      <qgc_addr>INADDR_ANY</qgc_addr>
      <qgc_udp_port>14550</qgc_udp_port>
      <hil_mode>false</hil_mode>
      <hil_state_level>false</hil_state_level>
      <vehicle_is_tailsitter>false</vehicle_is_tailsitter>
      <send_odometry>false</send_odometry>
      <motorSpeedCommandPubTopic>/gazebo/command/motor_speed</motorSpeedCommandPubTopic>
      <control_channels>
        <channel name="rotor1">
          <input_index>0</input_index>
          <input_offset>0</input_offset>
          <input_scaling>1000</input_scaling>
          <zero_position_disarmed>0</zero_position_disarmed>
          <zero_position_armed>100</zero_position_armed>
          <joint_control_type>velocity</joint_control_type>
          <joint_name>rotor_0_joint</joint_name>
        </channel>
        <channel name="rotor2">
          <input_index>1</input_index>
          <input_offset>0</input_offset>
          <input_scaling>1000</input_scaling>
          <zero_position_disarmed>0</zero_position_disarmed>
          <zero_position_armed>100</zero_position_armed>
          <joint_control_type>velocity</joint_control_type>
          <joint_name>rotor_1_joint</joint_name>
        </channel>
        <channel name="rotor3">
          <input_index>2</input_index>
          <input_offset>0</input_offset>
          <input_scaling>1000</input_scaling>
          <zero_position_disarmed>0</zero_position_disarmed>
          <zero_position_armed>100</zero_position_armed>
          <joint_control_type>velocity</joint_control_type>
          <joint_name>rotor_2_joint</joint_name>
        </channel>
        <channel name="rotor4">
          <input_index>3</input_index>
          <input_offset>0</input_offset>
          <input_scaling>1000</input_scaling>
          <zero_position_disarmed>0</zero_position_disarmed>
          <zero_position_armed>100</zero_position_armed>
          <joint_control_type>velocity</joint_control_type>
          <joint_name>rotor_3_joint</joint_name>
        </channel>
        <channel name="rotor5">
          <input_index>4</input_index>
          <input_offset>0</input_offset>
          <input_scaling>1000</input_scaling>
          <zero_position_disarmed>0</zero_position_disarmed>
          <zero_position_armed>100</zero_position_armed>
          <joint_control_type>velocity</joint_control_type>
          <joint_name>rotor_4_joint</joint_name>
        </channel>
        <channel name="rotor6">
          <input_index>5</input_index>
          <input_offset>0</input_offset>
          <input_scaling>1000</input_scaling>
          <zero_position_disarmed>0</zero_position_disarmed>
          <zero_position_armed>100</zero_position_armed>
          <joint_control_type>velocity</joint_control_type>
          <joint_name>rotor_5_joint</joint_name>
        </channel>
      </control_channels>
    </plugin>
  </gazebo>
  <static>0</static>
  <!-- IMU Link -->
  <link name="/imu_link">
    <inertial>
      <inertia ixx="1e-05" ixy="0" ixz="0" iyy="1e-05" iyz="0" izz="1e-05"/>
      <mass value="0.015"/>
      <!-- kg -->
      <origin rpy="0 0 0" xyz="0 0 0"/>
    </inertial>
  </link>
  <!-- IMU Joint -->
  <joint name="/imu_joint" type="revolute">
    <origin rpy="0 0 0" xyz="0 0 0"/>
    <parent link="base_link"/>
    <child link="/imu_link"/>
    <limit effort="0" lower="0" upper="0" velocity="0"/>
  </joint>
  <gazebo>
    <plugin filename="libgazebo_imu_plugin.so" name="rotors_gazebo_imu_plugin">
      <!-- See below for the details of parameters:
            https://github.com/ethz-asl/kalibr/wiki/IMU-Noise-Model-and-Intrinsics -->
      <robotNamespace></robotNamespace>
      <linkName>/imu_link</linkName>
      <imuTopic>/imu</imuTopic>
      <gyroscopeNoiseDensity>0.0003394</gyroscopeNoiseDensity>
      <gyroscopeRandomWalk>3.8785e-05</gyroscopeRandomWalk>
      <gyroscopeBiasCorrelationTime>1000.0</gyroscopeBiasCorrelationTime>
      <gyroscopeTurnOnBiasSigma>0.0087</gyroscopeTurnOnBiasSigma>
      <accelerometerNoiseDensity>0.004</accelerometerNoiseDensity>
      <accelerometerRandomWalk>0.006</accelerometerRandomWalk>
      <accelerometerBiasCorrelationTime>300.0</accelerometerBiasCorrelationTime>
      <accelerometerTurnOnBiasSigma>0.196</accelerometerTurnOnBiasSigma>
    </plugin>
  </gazebo>
  <!-- LiDAR Link -->
  <link name="lidar_link">
    <inertial>
      <mass value="0.3"/>
      <inertia ixx="0.00023701" ixy="0" ixz="0" iyy="0.00023618" iyz="0" izz="0.00014751"/>
    </inertial>
    <visual>
      <geometry>
        <mesh filename="package://F550_rd/meshes/hokuyo.STL" scale="1 1 1"/>
      </geometry>
    </visual>
  </link>
  <!-- Joint -->
  <joint name="lidar_joint" type="revolute">
    <origin rpy="0 0 0" xyz="0.044 0 0.0655"/>
    <child link="lidar_link"/>
    <parent link="base_link"/>
    <limit effort="0" lower="0" upper="0" velocity="0"/>
  </joint>
  <!-- Sensor -->
  <gazebo reference="lidar_link">
    <material>Gazebo/DarkGrey</material>
    <sensor name="laser" type="ray">
      <pose>0 0 0.055 0 0 0</pose>
      <ray>
        <scan>
          <horizontal>
            <samples>720</samples>
            <resolution>1</resolution>
            <min_angle>-3.14</min_angle>
            <max_angle>3.14</max_angle>
          </horizontal>
        </scan>
        <range>
          <min>0.1</min>
          <max>30</max>
          <resolution>0.01</resolution>
        </range>
        <noise>
          <type>gaussian</type>
          <mean>0.0</mean>
          <stddev>0.01</stddev>
        </noise>
      </ray>
      <plugin filename="libgazebo_ros_laser.so" name="LaserPlugin">
        <topicName>/laser/scan</topicName>
        <frameName>lidar_link</frameName>
      </plugin>
      <always_on>1</always_on>
      <update_rate>40</update_rate>
      <visualize>true</visualize>
    </sensor>
  </gazebo>
  <!-- Odroid -->
  <link name="odroid_link">
    <inertial>
      <origin rpy="0 0 0" xyz="0.0057413 0.00030748 -0.0052843"/>
      <mass value="0.08"/>
      <inertia ixx="4.4834E-06" ixy="3.2726E-07" ixz="1.7419E-07" iyy="6.5755E-06" iyz="1.4639E-08" izz="1.0308E-05"/>
    </inertial>
    <visual>
      <origin rpy="0 0 0" xyz="0 0 0"/>
      <geometry>
        <mesh filename="package://F550_rd/meshes/odroid_xu4.STL" scale="1 1 1"/>
      </geometry>
    </visual>
  </link>
  <joint name="odoroid_joint" type="fixed">
    <child link="odroid_link"/>
    <parent link="base_link"/>
    <origin rpy="0 0 0" xyz="-0.027 0 0.077"/>
  </joint>
  <gazebo reference="odroid_link">
    <material>Gazebo/DarkGrey</material>
  </gazebo>
</robot>
