<sdf version='1.6'>
  <model name='hexacopter'>
    <link name='base_link'>
      <pose frame=''>0 0 0 0 -0 0</pose>
      <inertial>
        <pose frame=''>0.015722 -0.13051 0.080871 0 -0 0</pose>
        <mass>0.925889</mass>
        <inertia>
          <ixx>0.0268683</ixx>
          <ixy>0.000597869</ixy>
          <ixz>0.000399198</ixz>
          <iyy>0.0225023</iyy>
          <iyz>-0.00332037</iyz>
          <izz>0.0434172</izz>
        </inertia>
      </inertial>
      <collision name='base_link_collision'>
        <pose frame=''>0 0 0 0 -0 0</pose>
        <geometry>
          <mesh>
            <scale>1 1 1</scale>
            <uri>model://f550_body/meshes/base_link.STL</uri>
          </mesh>
        </geometry>
      </collision>
      <collision name='base_link_fixed_joint_lump__wing1_collision_1'>
        <pose frame=''>-0.1989 -0.34112 0.014967 0 0 2.3562</pose>
        <geometry>
          <mesh>
            <scale>1 1 1</scale>
            <uri>model://f550_body/meshes/wing1.STL</uri>
          </mesh>
        </geometry>
      </collision>
      <collision name='base_link_fixed_joint_lump__wing2_collision_2'>
        <pose frame=''>0.068521 -0.17062 0.014967 -0 -0 -0.7854</pose>
        <geometry>
          <mesh>
            <scale>1 1 1</scale>
            <uri>model://f550_body/meshes/wing2.STL</uri>
          </mesh>
        </geometry>
      </collision>
      <collision name='base_link_fixed_joint_lump__wing3_collision_3'>
        <pose frame=''>0.27902 -0.27487 0.014967 -0 -0 -1.8326</pose>
        <geometry>
          <mesh>
            <scale>1 1 1</scale>
            <uri>model://f550_body/meshes/wing3.STL</uri>
          </mesh>
        </geometry>
      </collision>
      <collision name='base_link_fixed_joint_lump__wing4_collision_4'>
        <pose frame=''>-0.002392 -0.12731 0.014967 0 0 1.309</pose>
        <geometry>
          <mesh>
            <scale>1 1 1</scale>
            <uri>model://f550_body/meshes/wing4.STL</uri>
          </mesh>
        </geometry>
      </collision>
      <collision name='base_link_fixed_joint_lump__wing5_collision_5'>
        <pose frame=''>-0.004546 -0.21268 0.014967 -0 -0 -2.8798</pose>
        <geometry>
          <mesh>
            <scale>1 1 1</scale>
            <uri>model://f550_body/meshes/wing5.STL</uri>
          </mesh>
        </geometry>
      </collision>
      <collision name='base_link_fixed_joint_lump__wing6_collision_6'>
        <pose frame=''>-0.018538 0.10419 0.014967 -0 0 0.2618</pose>
        <geometry>
          <mesh>
            <scale>1 1 1</scale>
            <uri>model://f550_body/meshes/wing6.STL</uri>
          </mesh>
        </geometry>
      </collision>
      <visual name='base_link_visual'>
        <pose frame=''>0 0 0 0 -0 0</pose>
        <geometry>
          <mesh>
            <scale>1 1 1</scale>
            <uri>model://f550_body/meshes/base_link.STL</uri>
          </mesh>
        </geometry>
      </visual>
      <visual name='base_link_fixed_joint_lump__wing1_visual_1'>
        <pose frame=''>-0.1989 -0.34112 0.014967 0 0 2.3562</pose>
        <geometry>
          <mesh>
            <scale>1 1 1</scale>
            <uri>model://f550_body/meshes/wing1.STL</uri>
          </mesh>
        </geometry>
      </visual>
      <visual name='base_link_fixed_joint_lump__wing2_visual_2'>
        <pose frame=''>0.068521 -0.17062 0.014967 -0 -0 -0.7854</pose>
        <geometry>
          <mesh>
            <scale>1 1 1</scale>
            <uri>model://f550_body/meshes/wing2.STL</uri>
          </mesh>
        </geometry>
      </visual>
      <visual name='base_link_fixed_joint_lump__wing3_visual_3'>
        <pose frame=''>0.27902 -0.27487 0.014967 -0 -0 -1.8326</pose>
        <geometry>
          <mesh>
            <scale>1 1 1</scale>
            <uri>model://f550_body/meshes/wing3.STL</uri>
          </mesh>
        </geometry>
      </visual>
      <visual name='base_link_fixed_joint_lump__wing4_visual_4'>
        <pose frame=''>-0.002392 -0.12731 0.014967 0 0 1.309</pose>
        <geometry>
          <mesh>
            <scale>1 1 1</scale>
            <uri>model://f550_body/meshes/wing4.STL</uri>
          </mesh>
        </geometry>
      </visual>
      <visual name='base_link_fixed_joint_lump__wing5_visual_5'>
        <pose frame=''>-0.004546 -0.21268 0.014967 -0 -0 -2.8798</pose>
        <geometry>
          <mesh>
            <scale>1 1 1</scale>
            <uri>model://f550_body/meshes/wing5.STL</uri>
          </mesh>
        </geometry>
      </visual>
      <visual name='base_link_fixed_joint_lump__wing6_visual_6'>
        <pose frame=''>-0.018538 0.10419 0.014967 -0 0 0.2618</pose>
        <geometry>
          <mesh>
            <scale>1 1 1</scale>
            <uri>model://f550_body/meshes/wing6.STL</uri>
          </mesh>
        </geometry>
      </visual>
    </link>
    <link name='prop1'>
      <pose frame=''>-0.253401 -0.170619 0.0747 -0 0 0.4356</pose>
      <inertial>
        <pose frame=''>0 0 0.007853 0 -0 0</pose>
        <mass>0.0091837</mass>
        <inertia>
          <ixx>3.009e-07</ixx>
          <ixy>1.5042e-07</ixy>
          <ixz>-1.4325e-13</ixz>
          <iyy>3.4024e-05</iyy>
          <iyz>8.249e-15</iyz>
          <izz>3.4239e-05</izz>
        </inertia>
      </inertial>
      <collision name='prop1_collision'>
        <pose frame=''>0 0 0 0 -0 0</pose>
        <geometry>
          <mesh>
            <scale>1 1 1</scale>
            <uri>model://f550_body/meshes/prop1.STL</uri>
          </mesh>
        </geometry>
      </collision>
      <visual name='prop1_visual'>
        <pose frame=''>0 0 0 0 -0 0</pose>
        <geometry>
          <mesh>
            <scale>1 1 1</scale>
            <uri>model://f550_body/meshes/prop1.STL</uri>
          </mesh>
        </geometry>
      </visual>
    </link>
    <joint name='p1' type='revolute'>
      <child>prop1</child>
      <parent>base_link</parent>
      <axis>
        <xyz>-0 0 1</xyz>
        <limit>
          <lower>-1e+16</lower>
          <upper>1e+16</upper>
        </limit>
        <dynamics>
          <spring_reference>0</spring_reference>
          <spring_stiffness>0</spring_stiffness>
        </dynamics>
        <use_parent_model_frame>1</use_parent_model_frame>
      </axis>
    </joint>
    <link name='prop2'>
      <pose frame=''>0.293522 -0.17062 0.0747 -0 0 -0</pose>
      <inertial>
        <pose frame=''>-1e-06 0 0.007851 0 -0 0</pose>
        <mass>0.00919099</mass>
        <inertia>
          <ixx>3.00752e-07</ixx>
          <ixy>-1.44553e-07</ixy>
          <ixz>8.5917e-11</ixz>
          <iyy>3.41061e-05</iyy>
          <iyz>-4.1132e-12</iyz>
          <izz>3.43204e-05</izz>
        </inertia>
      </inertial>
      <collision name='prop2_collision'>
        <pose frame=''>0 0 0 0 -0 0</pose>
        <geometry>
          <mesh>
            <scale>1 1 1</scale>
            <uri>model://f550_body/meshes/prop2.STL</uri>
          </mesh>
        </geometry>
      </collision>
      <visual name='prop2_visual'>
        <pose frame=''>0 0 0 0 -0 0</pose>
        <geometry>
          <mesh>
            <scale>1 1 1</scale>
            <uri>model://f550_body/meshes/prop2.STL</uri>
          </mesh>
        </geometry>
      </visual>
    </link>
    <joint name='p2' type='revolute'>
      <child>prop2</child>
      <parent>base_link</parent>
      <axis>
        <xyz>0 0 1</xyz>
        <limit>
          <lower>-1e+16</lower>
          <upper>1e+16</upper>
        </limit>
        <dynamics>
          <spring_reference>0</spring_reference>
          <spring_stiffness>0</spring_stiffness>
        </dynamics>
        <use_parent_model_frame>1</use_parent_model_frame>
      </axis>
    </joint>
    <link name='prop3'>
      <pose frame=''>0.158611 -0.407319 0.0747 -0 -0 0</pose>
      <inertial>
        <pose frame=''>0 0 0.007853 0 -0 0</pose>
        <mass>0.00918372</mass>
        <inertia>
          <ixx>3.00902e-07</ixx>
          <ixy>1.50415e-07</ixy>
          <ixz>6.062e-15</ixz>
          <iyy>3.40245e-05</iyy>
          <iyz>1.65343e-14</iyz>
          <izz>3.4239e-05</izz>
        </inertia>
      </inertial>
      <collision name='prop3_collision'>
        <pose frame=''>0 0 0 0 -0 0</pose>
        <geometry>
          <mesh>
            <scale>1 1 1</scale>
            <uri>model://f550_body/meshes/prop3.STL</uri>
          </mesh>
        </geometry>
      </collision>
      <visual name='prop3_visual'>
        <pose frame=''>0 0 0 0 -0 0</pose>
        <geometry>
          <mesh>
            <scale>1 1 1</scale>
            <uri>model://f550_body/meshes/prop3.STL</uri>
          </mesh>
        </geometry>
      </visual>
    </link>
    <joint name='p3' type='revolute'>
      <child>prop3</child>
      <parent>base_link</parent>
      <axis>
        <xyz>-0 0 1</xyz>
        <limit>
          <lower>-1e+16</lower>
          <upper>1e+16</upper>
        </limit>
        <dynamics>
          <spring_reference>0</spring_reference>
          <spring_stiffness>0</spring_stiffness>
        </dynamics>
        <use_parent_model_frame>1</use_parent_model_frame>
      </axis>
    </joint>
    <link name='prop4'>
      <pose frame=''>-0.114893 0.067547 0.0747 -0 0 -0</pose>
      <inertial>
        <pose frame=''>-1e-06 0 0.007851 0 -0 0</pose>
        <mass>0.00919099</mass>
        <inertia>
          <ixx>3.00748e-07</ixx>
          <ixy>-1.44554e-07</ixy>
          <ixz>7.91378e-11</ixz>
          <iyy>3.4106e-05</iyy>
          <iyz>-3.43689e-12</iyz>
          <izz>3.43204e-05</izz>
        </inertia>
      </inertial>
      <collision name='prop4_collision'>
        <pose frame=''>0 0 0 0 -0 0</pose>
        <geometry>
          <mesh>
            <scale>1 1 1</scale>
            <uri>model://f550_body/meshes/prop4.STL</uri>
          </mesh>
        </geometry>
      </collision>
      <visual name='prop4_visual'>
        <pose frame=''>0 0 0 0 -0 0</pose>
        <geometry>
          <mesh>
            <scale>1 1 1</scale>
            <uri>model://f550_body/meshes/prop4.STL</uri>
          </mesh>
        </geometry>
      </visual>
    </link>
    <joint name='p4' type='revolute'>
      <child>prop4</child>
      <parent>base_link</parent>
      <axis>
        <xyz>0 0 1</xyz>
        <limit>
          <lower>-1e+16</lower>
          <upper>1e+16</upper>
        </limit>
        <dynamics>
          <spring_reference>0</spring_reference>
          <spring_stiffness>0</spring_stiffness>
        </dynamics>
        <use_parent_model_frame>1</use_parent_model_frame>
      </axis>
    </joint>
    <link name='prop5'>
      <pose frame=''>-0.117048 -0.407536 0.0747 -0 0 0.405085</pose>
      <inertial>
        <pose frame=''>-1e-06 0 0.007851 0 -0 0</pose>
        <mass>0.009191</mass>
        <inertia>
          <ixx>3.0076e-07</ixx>
          <ixy>-1.4455e-07</ixy>
          <ixz>7.8274e-11</ixz>
          <iyy>3.4106e-05</iyy>
          <iyz>-3.5802e-12</iyz>
          <izz>3.432e-05</izz>
        </inertia>
      </inertial>
      <collision name='prop5_collision'>
        <pose frame=''>0 0 0 0 -0 0</pose>
        <geometry>
          <mesh>
            <scale>1 1 1</scale>
            <uri>model://f550_body/meshes/prop5.STL</uri>
          </mesh>
        </geometry>
      </collision>
      <visual name='prop5_visual'>
        <pose frame=''>0 0 0 0 -0 0</pose>
        <geometry>
          <mesh>
            <scale>1 1 1</scale>
            <uri>model://f550_body/meshes/prop5.STL</uri>
          </mesh>
        </geometry>
      </visual>
    </link>
    <joint name='p5' type='revolute'>
      <child>prop5</child>
      <parent>base_link</parent>
      <axis>
        <xyz>-0 0 1</xyz>
        <limit>
          <lower>-1e+16</lower>
          <upper>1e+16</upper>
        </limit>
        <dynamics>
          <spring_reference>0</spring_reference>
          <spring_stiffness>0</spring_stiffness>
        </dynamics>
        <use_parent_model_frame>1</use_parent_model_frame>
      </axis>
    </joint>
    <link name='prop6'>
      <pose frame=''>0.15637 0.066138 0.0747 0 -0 -2.4444</pose>
      <inertial>
        <pose frame=''>-0 0 0.007853 0 -0 0</pose>
        <mass>0.0091837</mass>
        <inertia>
          <ixx>3.009e-07</ixx>
          <ixy>1.5042e-07</ixy>
          <ixz>-5.3597e-12</ixz>
          <iyy>3.4025e-05</iyy>
          <iyz>-4.8165e-13</iyz>
          <izz>3.4239e-05</izz>
        </inertia>
      </inertial>
      <collision name='prop6_collision'>
        <pose frame=''>0 0 0 0 -0 0</pose>
        <geometry>
          <mesh>
            <scale>1 1 1</scale>
            <uri>model://f550_body/meshes/prop6.STL</uri>
          </mesh>
        </geometry>
      </collision>
      <visual name='prop6_visual'>
        <pose frame=''>0 0 0 0 -0 0</pose>
        <geometry>
          <mesh>
            <scale>1 1 1</scale>
            <uri>model://f550_body/meshes/prop6.STL</uri>
          </mesh>
        </geometry>
      </visual>
    </link>
    <joint name='p6' type='revolute'>
      <child>prop6</child>
      <parent>base_link</parent>
      <axis>
        <xyz>0 0 1</xyz>
        <limit>
          <lower>-1e+16</lower>
          <upper>1e+16</upper>
        </limit>
        <dynamics>
          <spring_reference>0</spring_reference>
          <spring_stiffness>0</spring_stiffness>
        </dynamics>
        <use_parent_model_frame>1</use_parent_model_frame>
      </axis>
    </joint>
  </model>
</sdf>

