<?xml version="1.0" ?>
<sdf version='1.6'>
  <model name='hexarotor'>
    <link name='base_link'>
      <pose frame=''>0 0 0 0 -0 0</pose>
      <inertial>
        <pose frame=''>0.015722 -0.13051 0.080871 0 -0 0</pose>
        <mass>0.925889</mass>
        <inertia>
          <ixx>0.0268683</ixx>
          <ixy>0.000597869</ixy>
          <ixz>0.000399198</ixz>
          <iyy>0.0225023</iyy>
          <iyz>-0.00332037</iyz>
          <izz>0.0434172</izz>
        </inertia>
      </inertial>
      <collision name='base_link_collision'>
        <pose frame=''>0 0 0 0 -0 0</pose>
        <geometry>
          <mesh>
            <scale>1 1 1</scale>
            <uri>model://hexarotor/meshes/base_link.STL</uri>
          </mesh>
        </geometry>
      </collision>
      <collision name='base_link_fixed_joint_lump__wing1_collision_1'>
        <pose frame=''>-0.1989 -0.34112 0.014967 0 0 2.3562</pose>
        <geometry>
          <mesh>
            <scale>1 1 1</scale>
            <uri>model://hexarotor/meshes/wing1.STL</uri>
          </mesh>
        </geometry>
      </collision>
      <collision name='base_link_fixed_joint_lump__wing2_collision_2'>
        <pose frame=''>0.068521 -0.17062 0.014967 -0 -0 -0.7854</pose>
        <geometry>
          <mesh>
            <scale>1 1 1</scale>
            <uri>model://hexarotor/meshes/wing2.STL</uri>
          </mesh>
        </geometry>
      </collision>
      <collision name='base_link_fixed_joint_lump__wing3_collision_3'>
        <pose frame=''>0.27902 -0.27487 0.014967 -0 -0 -1.8326</pose>
        <geometry>
          <mesh>
            <scale>1 1 1</scale>
            <uri>model://hexarotor/meshes/wing3.STL</uri>
          </mesh>
        </geometry>
      </collision>
      <collision name='base_link_fixed_joint_lump__wing4_collision_4'>
        <pose frame=''>-0.002392 -0.12731 0.014967 0 0 1.309</pose>
        <geometry>
          <mesh>
            <scale>1 1 1</scale>
            <uri>model://hexarotor/meshes/wing4.STL</uri>
          </mesh>
        </geometry>
      </collision>
      <collision name='base_link_fixed_joint_lump__wing5_collision_5'>
        <pose frame=''>-0.004546 -0.21268 0.014967 -0 -0 -2.8798</pose>
        <geometry>
          <mesh>
            <scale>1 1 1</scale>
            <uri>model://hexarotor/meshes/wing5.STL</uri>
          </mesh>
        </geometry>
      </collision>
      <collision name='base_link_fixed_joint_lump__wing6_collision_6'>
        <pose frame=''>-0.018538 0.10419 0.014967 -0 0 0.2618</pose>
        <geometry>
          <mesh>
            <scale>1 1 1</scale>
            <uri>model://hexarotor/meshes/wing6.STL</uri>
          </mesh>
        </geometry>
      </collision>
      <visual name='base_link_visual'>
        <pose frame=''>0 0 0 0 -0 0</pose>
        <geometry>
          <mesh>
            <scale>1 1 1</scale>
            <uri>model://hexarotor/meshes/base_link.STL</uri>
          </mesh>
        </geometry>
      </visual>
      <visual name='base_link_fixed_joint_lump__wing1_visual_1'>
        <pose frame=''>-0.1989 -0.34112 0.014967 0 0 2.3562</pose>
        <geometry>
          <mesh>
            <scale>1 1 1</scale>
            <uri>model://hexarotor/meshes/wing1.STL</uri>
          </mesh>
        </geometry>
      </visual>
      <visual name='base_link_fixed_joint_lump__wing2_visual_2'>
        <pose frame=''>0.068521 -0.17062 0.014967 -0 -0 -0.7854</pose>
        <geometry>
          <mesh>
            <scale>1 1 1</scale>
            <uri>model://hexarotor/meshes/wing2.STL</uri>
          </mesh>
        </geometry>
      </visual>
      <visual name='base_link_fixed_joint_lump__wing3_visual_3'>
        <pose frame=''>0.27902 -0.27487 0.014967 -0 -0 -1.8326</pose>
        <geometry>
          <mesh>
            <scale>1 1 1</scale>
            <uri>model://hexarotor/meshes/wing3.STL</uri>
          </mesh>
        </geometry>
      </visual>
      <visual name='base_link_fixed_joint_lump__wing4_visual_4'>
        <pose frame=''>-0.002392 -0.12731 0.014967 0 0 1.309</pose>
        <geometry>
          <mesh>
            <scale>1 1 1</scale>
            <uri>model://hexarotor/meshes/wing4.STL</uri>
          </mesh>
        </geometry>
      </visual>
      <visual name='base_link_fixed_joint_lump__wing5_visual_5'>
        <pose frame=''>-0.004546 -0.21268 0.014967 -0 -0 -2.8798</pose>
        <geometry>
          <mesh>
            <scale>1 1 1</scale>
            <uri>model://hexarotor/meshes/wing5.STL</uri>
          </mesh>
        </geometry>
      </visual>
      <visual name='base_link_fixed_joint_lump__wing6_visual_6'>
        <pose frame=''>-0.018538 0.10419 0.014967 -0 0 0.2618</pose>
        <geometry>
          <mesh>
            <scale>1 1 1</scale>
            <uri>model://hexarotor/meshes/wing6.STL</uri>
          </mesh>
        </geometry>
      </visual>
    </link>
    <link name='/imu_link'>
      <pose frame=''>0 0 0 0 -0 0</pose>
      <inertial>
        <pose frame=''>0 0 0 0 -0 0</pose>
        <mass>0.015</mass>
        <inertia>
          <ixx>1e-05</ixx>
          <ixy>0</ixy>
          <ixz>0</ixz>
          <iyy>1e-05</iyy>
          <iyz>0</iyz>
          <izz>1e-05</izz>
        </inertia>
      </inertial>
    </link>
    <joint name='/imu_joint' type='revolute'>
      <child>/imu_link</child>
      <parent>base_link</parent>
      <axis>
        <xyz>1 0 0</xyz>
        <limit>
          <lower>0</lower>
          <upper>0</upper>
          <effort>0</effort>
          <velocity>0</velocity>
        </limit>
        <dynamics>
          <spring_reference>0</spring_reference>
          <spring_stiffness>0</spring_stiffness>
        </dynamics>
        <use_parent_model_frame>1</use_parent_model_frame>
      </axis>
    <link name='prop1'>
      <pose frame=''>-0.253401 -0.170619 0.0747 -0 0 0.4356</pose>
      <inertial>
        <pose frame=''>0 0 0.007853 0 -0 0</pose>
        <mass>0.0091837</mass>
        <inertia>
          <ixx>3.009e-07</ixx>
          <ixy>1.5042e-07</ixy>
          <ixz>-1.4325e-13</ixz>
          <iyy>3.4024e-05</iyy>
          <iyz>8.249e-15</iyz>
          <izz>3.4239e-05</izz>
        </inertia>
      </inertial>
      <collision name='prop1_collision'>
        <pose frame=''>0 0 0 0 -0 0</pose>
        <geometry>
          <mesh>
            <scale>1 1 1</scale>
            <uri>model://hexarotor/meshes/prop1.STL</uri>
          </mesh>
        </geometry>
      </collision>
      <visual name='prop1_visual'>
        <pose frame=''>0 0 0 0 -0 0</pose>
        <geometry>
          <mesh>
            <scale>1 1 1</scale>
            <uri>model://hexarotor/meshes/prop1.STL</uri>
          </mesh>
        </geometry>
      </visual>
    </link>
    <joint name='p1' type='revolute'>
      <child>prop1</child>
      <parent>base_link</parent>
      <axis>
        <xyz>-0 0 1</xyz>
        <limit>
          <lower>-1e+16</lower>
          <upper>1e+16</upper>
        </limit>
        <dynamics>
          <spring_reference>0</spring_reference>
          <spring_stiffness>0</spring_stiffness>
        </dynamics>
        <use_parent_model_frame>1</use_parent_model_frame>
      </axis>
    </joint>
    <link name='prop2'>
      <pose frame=''>0.293522 -0.17062 0.0747 -0 0 -0</pose>
      <inertial>
        <pose frame=''>-1e-06 0 0.007851 0 -0 0</pose>
        <mass>0.00919099</mass>
        <inertia>
          <ixx>3.00752e-07</ixx>
          <ixy>-1.44553e-07</ixy>
          <ixz>8.5917e-11</ixz>
          <iyy>3.41061e-05</iyy>
          <iyz>-4.1132e-12</iyz>
          <izz>3.43204e-05</izz>
        </inertia>
      </inertial>
      <collision name='prop2_collision'>
        <pose frame=''>0 0 0 0 -0 0</pose>
        <geometry>
          <mesh>
            <scale>1 1 1</scale>
            <uri>model://hexarotor/meshes/prop2.STL</uri>
          </mesh>
        </geometry>
      </collision>
      <visual name='prop2_visual'>
        <pose frame=''>0 0 0 0 -0 0</pose>
        <geometry>
          <mesh>
            <scale>1 1 1</scale>
            <uri>model://hexarotor/meshes/prop2.STL</uri>
          </mesh>
        </geometry>
      </visual>
    </link>
    <joint name='p2' type='revolute'>
      <child>prop2</child>
      <parent>base_link</parent>
      <axis>
        <xyz>0 0 1</xyz>
        <limit>
          <lower>-1e+16</lower>
          <upper>1e+16</upper>
        </limit>
        <dynamics>
          <spring_reference>0</spring_reference>
          <spring_stiffness>0</spring_stiffness>
        </dynamics>
        <use_parent_model_frame>1</use_parent_model_frame>
      </axis>
    </joint>
    <link name='prop3'>
      <pose frame=''>0.158611 -0.407319 0.0747 -0 -0 0</pose>
      <inertial>
        <pose frame=''>0 0 0.007853 0 -0 0</pose>
        <mass>0.00918372</mass>
        <inertia>
          <ixx>3.00902e-07</ixx>
          <ixy>1.50415e-07</ixy>
          <ixz>6.062e-15</ixz>
          <iyy>3.40245e-05</iyy>
          <iyz>1.65343e-14</iyz>
          <izz>3.4239e-05</izz>
        </inertia>
      </inertial>
      <collision name='prop3_collision'>
        <pose frame=''>0 0 0 0 -0 0</pose>
        <geometry>
          <mesh>
            <scale>1 1 1</scale>
            <uri>model://hexarotor/meshes/prop3.STL</uri>
          </mesh>
        </geometry>
      </collision>
      <visual name='prop3_visual'>
        <pose frame=''>0 0 0 0 -0 0</pose>
        <geometry>
          <mesh>
            <scale>1 1 1</scale>
            <uri>model://hexarotor/meshes/prop3.STL</uri>
          </mesh>
        </geometry>
      </visual>
    </link>
    <joint name='p3' type='revolute'>
      <child>prop3</child>
      <parent>base_link</parent>
      <axis>
        <xyz>-0 0 1</xyz>
        <limit>
          <lower>-1e+16</lower>
          <upper>1e+16</upper>
        </limit>
        <dynamics>
          <spring_reference>0</spring_reference>
          <spring_stiffness>0</spring_stiffness>
        </dynamics>
        <use_parent_model_frame>1</use_parent_model_frame>
      </axis>
    </joint>
    <link name='prop4'>
      <pose frame=''>-0.114893 0.067547 0.0747 -0 0 -0</pose>
      <inertial>
        <pose frame=''>-1e-06 0 0.007851 0 -0 0</pose>
        <mass>0.00919099</mass>
        <inertia>
          <ixx>3.00748e-07</ixx>
          <ixy>-1.44554e-07</ixy>
          <ixz>7.91378e-11</ixz>
          <iyy>3.4106e-05</iyy>
          <iyz>-3.43689e-12</iyz>
          <izz>3.43204e-05</izz>
        </inertia>
      </inertial>
      <collision name='prop4_collision'>
        <pose frame=''>0 0 0 0 -0 0</pose>
        <geometry>
          <mesh>
            <scale>1 1 1</scale>
            <uri>model://hexarotor/meshes/prop4.STL</uri>
          </mesh>
        </geometry>
      </collision>
      <visual name='prop4_visual'>
        <pose frame=''>0 0 0 0 -0 0</pose>
        <geometry>
          <mesh>
            <scale>1 1 1</scale>
            <uri>model://hexarotor/meshes/prop4.STL</uri>
          </mesh>
        </geometry>
      </visual>
    </link>
    <joint name='p4' type='revolute'>
      <child>prop4</child>
      <parent>base_link</parent>
      <axis>
        <xyz>0 0 1</xyz>
        <limit>
          <lower>-1e+16</lower>
          <upper>1e+16</upper>
        </limit>
        <dynamics>
          <spring_reference>0</spring_reference>
          <spring_stiffness>0</spring_stiffness>
        </dynamics>
        <use_parent_model_frame>1</use_parent_model_frame>
      </axis>
    </joint>
    <link name='prop5'>
      <pose frame=''>-0.117048 -0.407536 0.0747 -0 0 0.405085</pose>
      <inertial>
        <pose frame=''>-1e-06 0 0.007851 0 -0 0</pose>
        <mass>0.009191</mass>
        <inertia>
          <ixx>3.0076e-07</ixx>
          <ixy>-1.4455e-07</ixy>
          <ixz>7.8274e-11</ixz>
          <iyy>3.4106e-05</iyy>
          <iyz>-3.5802e-12</iyz>
          <izz>3.432e-05</izz>
        </inertia>
      </inertial>
      <collision name='prop5_collision'>
        <pose frame=''>0 0 0 0 -0 0</pose>
        <geometry>
          <mesh>
            <scale>1 1 1</scale>
            <uri>model://hexarotor/meshes/prop5.STL</uri>
          </mesh>
        </geometry>
      </collision>prop1
      <visual name='prop5_visual'>
        <pose frame=''>0 0 0 0 -0 0</pose>
        <geometry>
          <mesh>
            <scale>1 1 1</scale>
            <uri>model://hexarotor/meshes/prop5.STL</uri>
          </mesh>
        </geometry>
      </visual>
    </link>
    <joint name='p5' type='revolute'>
      <child>prop5</child>
      <parent>base_link</parent>
      <axis>
        <xyz>-0 0 1</xyz>
        <limit>
          <lower>-1e+16</lower>
          <upper>1e+16</upper>
        </limit>
        <dynamics>
          <spring_reference>0</spring_reference>
          <spring_stiffness>0</spring_stiffness>
        </dynamics>
        <use_parent_model_frame>1</use_parent_model_frame>
      </axis>
    </joint>
    <link name='prop6'>
      <pose frame=''>0.15637 0.066138 0.0747 0 -0 -2.4444</pose>
      <inertial>
        <pose frame=''>-0 0 0.007853 0 -0 0</pose>
        <mass>0.0091837</mass>
        <inertia>
          <ixx>3.009e-07</ixx>
          <ixy>1.5042e-07</ixy>
          <ixz>-5.3597e-12</ixz>
          <iyy>3.4025e-05</iyy>
          <iyz>-4.8165e-13</iyz>
          <izz>3.4239e-05</izz>
        </inertia>
      </inertial>
      <collision name='prop6_collision'>
        <pose frame=''>0 0 0 0 -0 0</pose>
        <geometry>
          <mesh>
            <scale>1 1 1</scale>
            <uri>model://hexarotor/meshes/prop6.STL</uri>
          </mesh>
        </geometry>
      </collision>
      <visual name='prop6_visual'>
        <pose frame=''>0 0 0 0 -0 0</pose>
        <geometry>
          <mesh>
            <scale>1 1 1</scale>
            <uri>model://hexarotor/meshes/prop6.STL</uri>
          </mesh>
        </geometry>
      </visual>
    </link>
    <joint name='p6' type='revolute'>
      <child>prop6</child>
      <parent>base_link</parent>
      <axis>
        <xyz>0 0 1</xyz>
        <limit>
          <lower>-1e+16</lower>
          <upper>1e+16</upper>
        </limit>
        <dynamics>
          <spring_reference>0</spring_reference>
          <spring_stiffness>0</spring_stiffness>
        </dynamics>
        <use_parent_model_frame>1</use_parent_model_frame>
      </axis>
    </joint>
 <plugin name='rosbag' filename='librotors_gazebo_multirotor_base_plugin.so'>
      <robotNamespace/>
      <linkName>base_link</linkName>
      <rotorVelocitySlowdownSim>10</rotorVelocitySlowdownSim>
    </plugin>
    <plugin name='prop1_model' filename='librotors_gazebo_motor_model.so'>
      <robotNamespace/>
      <jointName>p1</jointName>
      <linkName>prop1</linkName>
      <turningDirection>cw</turningDirection>
      <timeConstantUp>0.0125</timeConstantUp>
      <timeConstantDown>0.025</timeConstantDown>
      <maxRotVelocity>1100</maxRotVelocity>
      <motorConstant>8.54858e-06</motorConstant>
      <momentConstant>0.06</momentConstant>
      <commandSubTopic>/gazebo/command/motor_speed</commandSubTopic>
      <motorNumber>0</motorNumber>
      <rotorDragCoefficient>0.000806428</rotorDragCoefficient>
      <rollingMomentCoefficient>1e-06</rollingMomentCoefficient>
      <motorSpeedPubTopic>/motor_speed/0</motorSpeedPubTopic>
      <rotorVelocitySlowdownSim>10</rotorVelocitySlowdownSim>
    </plugin>
    <plugin name='prop2_model' filename='librotors_gazebo_motor_model.so'>
      <robotNamespace/>
      <jointName>p2</jointName>
      <linkName>prop2</linkName>
      <turningDirection>ccw</turningDirection>
      <timeConstantUp>0.0125</timeConstantUp>
      <timeConstantDown>0.025</timeConstantDown>
      <maxRotVelocity>1100</maxRotVelocity>
      <motorConstant>8.54858e-06</motorConstant>
      <momentConstant>0.06</momentConstant>
      <commandSubTopic>/gazebo/command/motor_speed</commandSubTopic>
      <motorNumber>1</motorNumber>
      <rotorDragCoefficient>0.000806428</rotorDragCoefficient>
      <rollingMomentCoefficient>1e-06</rollingMomentCoefficient>
      <motorSpeedPubTopic>/motor_speed/1</motorSpeedPubTopic>
      <rotorVelocitySlowdownSim>10</rotorVelocitySlowdownSim>
    </plugin>
    <plugin name='prop3_model' filename='librotors_gazebo_motor_model.so'>
      <robotNamespace/>
      <jointName>p3</jointName>
      <linkName>prop3</linkName>
      <turningDirection>cw</turningDirection>
      <timeConstantUp>0.0125</timeConstantUp>
      <timeConstantDown>0.025</timeConstantDown>
      <maxRotVelocity>1100</maxRotVelocity>
      <motorConstant>8.54858e-06</motorConstant>
      <momentConstant>0.06</momentConstant>
      <commandSubTopic>/gazebo/command/motor_speed</commandSubTopic>
      <motorNumber>2</motorNumber>
      <rotorDragCoefficient>0.000806428</rotorDragCoefficient>
      <rollingMomentCoefficient>1e-06</rollingMomentCoefficient>
      <motorSpeedPubTopic>/motor_speed/2</motorSpeedPubTopic>
      <rotorVelocitySlowdownSim>10</rotorVelocitySlowdownSim>
    </plugin>
    <plugin name='prop4_model' filename='librotors_gazebo_motor_model.so'>
      <robotNamespace/>
      <jointName>p4</jointName>
      <linkName>prop4</linkName>
      <turningDirection>ccw</turningDirection>
      <timeConstantUp>0.0125</timeConstantUp>
      <timeConstantDown>0.025</timeConstantDown>
      <maxRotVelocity>1100</maxRotVelocity>
      <motorConstant>8.54858e-06</motorConstant>
      <momentConstant>0.06</momentConstant>
      <commandSubTopic>/gazebo/command/motor_speed</commandSubTopic>
      <motorNumber>3</motorNumber>
      <rotorDragCoefficient>0.000806428</rotorDragCoefficient>
      <rollingMomentCoefficient>1e-06</rollingMomentCoefficient>
      <motorSpeedPubTopic>/motor_speed/3</motorSpeedPubTopic>
      <rotorVelocitySlowdownSim>10</rotorVelocitySlowdownSim>
    </plugin>
   <plugin name='prop5_model' filename='librotors_gazebo_motor_model.so'>
      <robotNamespace/>
      <jointName>p5</jointName>
      <linkName>prop5</linkName>
      <turningDirection>ccw</turningDirection>
      <timeConstantUp>0.0125</timeConstantUp>
      <timeConstantDown>0.025</timeConstantDown>
      <maxRotVelocity>1100</maxRotVelocity>
      <motorConstant>8.54858e-06</motorConstant>
      <momentConstant>0.06</momentConstant>
      <commandSubTopic>/gazebo/command/motor_speed</commandSubTopic>
      <motorNumber>4</motorNumber>
      <rotorDragCoefficient>0.000806428</rotorDragCoefficient>
      <rollingMomentCoefficient>1e-06</rollingMomentCoefficient>
      <motorSpeedPubTopic>/motor_speed/4</motorSpeedPubTopic>
      <rotorVelocitySlowdownSim>10</rotorVelocitySlowdownSim>
    </plugin>
   <plugin name='prop6_model' filename='librotors_gazebo_motor_model.so'>
      <robotNamespace/>
      <jointName>p6</jointName>
      <linkName>prop6</linkName>
      <turningDirection>cw</turningDirection>
      <timeConstantUp>0.0125</timeConstantUp>
      <timeConstantDown>0.025</timeConstantDown>
      <maxRotVelocity>1100</maxRotVelocity>
      <motorConstant>8.54858e-06</motorConstant>
      <momentConstant>0.06</momentConstant>
      <commandSubTopic>/gazebo/command/motor_speed</commandSubTopic>
      <motorNumber>5</motorNumber>
      <rotorDragCoefficient>0.000806428</rotorDragCoefficient>
      <rollingMomentCoefficient>1e-06</rollingMomentCoefficient>
      <motorSpeedPubTopic>/motor_speed/5</motorSpeedPubTopic>
      <rotorVelocitySlowdownSim>10</rotorVelocitySlowdownSim>
    </plugin>
    <plugin name='gps_plugin' filename='libgazebo_gps_plugin.so'>
      <robotNamespace/>
      <gpsNoise>true</gpsNoise>
    </plugin>
    <plugin name='mavlink_interface' filename='librotors_gazebo_mavlink_interface.so'>
      <robotNamespace/>
      <imuSubTopic>/imu</imuSubTopic>
      <mavlink_addr>INADDR_ANY</mavlink_addr>
      <mavlink_udp_port>14560</mavlink_udp_port>
      <motorSpeedCommandPubTopic>/gazebo/command/motor_speed</motorSpeedCommandPubTopic>
      <control_channels>
        <channel name='rotor1'>
          <input_index>0</input_index>
          <input_offset>0</input_offset>
          <input_scaling>1000</input_scaling>
          <zero_position_disarmed>0</zero_position_disarmed>
          <zero_position_armed>100</zero_position_armed>
          <joint_control_type>velocity</joint_control_type>
        </channel>
        <channel name='rotor2'>
          <input_index>1</input_index>
          <input_offset>0</input_offset>
          <input_scaling>1000</input_scaling>
          <zero_position_disarmed>0</zero_position_disarmed>
          <zero_position_armed>100</zero_position_armed>
          <joint_control_type>velocity</joint_control_type>
        </channel>
        <channel name='rotor3'>
          <input_index>2</input_index>
          <input_offset>0</input_offset>
          <input_scaling>1000</input_scaling>
          <zero_position_disarmed>0</zero_position_disarmed>
          <zero_position_armed>100</zero_position_armed>
          <joint_control_type>velocity</joint_control_type>
        </channel>
        <channel name='rotor4'>
          <input_index>3</input_index>
          <input_offset>0</input_offset>
          <input_scaling>1000</input_scaling>
          <zero_position_disarmed>0</zero_position_disarmed>
          <zero_position_armed>100</zero_position_armed>
          <joint_control_type>velocity</joint_control_type>
        </channel>
         <channel name='rotor5'>
          <input_index>4</input_index>
          <input_offset>0</input_offset>
          <input_scaling>1000</input_scaling>
          <zero_position_disarmed>0</zero_position_disarmed>
          <zero_position_armed>100</zero_position_armed>
          <joint_control_type>velocity</joint_control_type>
        </channel>
         <channel name='rotor6'>
          <input_index>5</input_index>
          <input_offset>0</input_offset>
          <input_scaling>1000</input_scaling>
          <zero_position_disarmed>0</zero_position_disarmed>
          <zero_position_armed>100</zero_position_armed>
          <joint_control_type>velocity</joint_control_type>
        </channel>
        <channel name='rotor7'>
          <input_index>6</input_index>
          <input_offset>0</input_offset>
          <input_scaling>0.524</input_scaling>
          <zero_position_disarmed>0</zero_position_disarmed>
          <zero_position_armed>0</zero_position_armed>
          <joint_control_type>position</joint_control_type>
          <joint_name>zephyr_delta_wing::flap_right_joint</joint_name>
          <joint_control_pid>
            <p>10.0</p>
            <i>0</i>
            <d>0</d>
            <iMax>0</iMax>
            <iMin>0</iMin>
            <cmdMax>20</cmdMax>
            <cmdMin>-20</cmdMin>
          </joint_control_pid>
        </channel>
        <channel name='rotor8'>
          <input_index>7</input_index>
          <input_offset>0</input_offset>
          <input_scaling>0.524</input_scaling>
          <zero_position_disarmed>0</zero_position_disarmed>
          <zero_position_armed>0</zero_position_armed>
          <joint_control_type>position</joint_control_type>
        </channel>
      </control_channels>
    </plugin>
    <static>0</static>
    <plugin name='rotors_gazebo_imu_plugin' filename='librotors_gazebo_imu_plugin.so'>
      <robotNamespace/>
      <linkName>/imu_link</linkName>
      <imuTopic>/imu</imuTopic>
      <gyroscopeNoiseDensity>0.0003394</gyroscopeNoiseDensity>
      <gyroscopeRandomWalk>3.8785e-05</gyroscopeRandomWalk>
      <gyroscopeBiasCorrelationTime>1000.0</gyroscopeBiasCorrelationTime>
      <gyroscopeTurnOnBiasSigma>0.0087</gyroscopeTurnOnBiasSigma>
      <accelerometerNoiseDensity>0.004</accelerometerNoiseDensity>
      <accelerometerRandomWalk>0.006</accelerometerRandomWalk>
      <accelerometerBiasCorrelationTime>300.0</accelerometerBiasCorrelationTime>
      <accelerometerTurnOnBiasSigma>0.196</accelerometerTurnOnBiasSigma>
    </plugin>
  </model>
</sdf>

