<robot
  name="f550_rd_basic_v1">
  <link
    name="base_link">
    <inertial>
      <origin
        xyz="0 0 0"
        rpy="0 0 0" />
      <mass
        value="1" />
      <inertia
        ixx="0.00067479"
        ixy="-6.0421E-07"
        ixz="-7.5099E-07"
        iyy="0.0010896"
        iyz="1.8163E-06"
        izz="0.00064988" />
    </inertial>
    <visual>
      <origin
        xyz="0 0 0"
        rpy="0 0 0" />
      <geometry>
        <mesh
          filename="package://f550_rd_basic_v1/meshes/base_link.STL" />
      </geometry>
      <material
        name="">
        <color
          rgba="0.92941 0.92941 0.92941 1" />
      </material>
    </visual>
    <collision>
      <origin
        xyz="0 0 0"
        rpy="0 0 0" />
      <geometry>
        <mesh
          filename="package://f550_rd_basic_v1/meshes/base_link.STL" />
      </geometry>
    </collision>
  </link>
  <link
    name="wing1">
    <inertial>
      <origin
        xyz="0.12144 -0.11968 0.038426"
        rpy="0 0 0" />
      <mass
        value="0.11819" />
      <inertia
        ixx="0.0003171"
        ixy="-0.00028167"
        ixz="-4.3423E-05"
        iyy="0.00031709"
        iyz="-4.3436E-05"
        izz="0.0005792" />
    </inertial>
    <visual>
      <origin
        xyz="0 0 0"
        rpy="0 0 0" />
      <geometry>
        <mesh
          filename="package://f550_rd_basic_v1/meshes/wing1.STL" />
      </geometry>
      <material
        name="">
        <color
          rgba="0.75294 0.75294 0.75294 1" />
      </material>
    </visual>
    <collision>
      <origin
        xyz="0 0 0"
        rpy="0 0 0" />
      <geometry>
        <mesh
          filename="package://f550_rd_basic_v1/meshes/wing1.STL" />
      </geometry>
    </collision>
  </link>
  <joint
    name="w1"
    type="fixed">
    <origin
      xyz="-0.219500442258882 -0.17050044149774 -0.0402465423967925"
      rpy="4.32963728535971E-17 4.32963728535964E-17 2.35619449019235" />
    <parent
      link="base_link" />
    <child
      link="wing1" />
    <axis
      xyz="0 0 0" />
  </joint>
  <link
    name="prop1">
    <inertial>
      <origin
        xyz="1.6083E-08 6.1968E-09 0.0078525"
        rpy="0 0 0" />
      <mass
        value="0.0091837" />
      <inertia
        ixx="3.009E-07"
        ixy="1.5042E-07"
        ixz="5.8166E-13"
        iyy="3.4024E-05"
        iyz="-7.7721E-14"
        izz="3.4239E-05" />
    </inertial>
    <visual>
      <origin
        xyz="0 0 0"
        rpy="0 0 0" />
      <geometry>
        <mesh
          filename="package://f550_rd_basic_v1/meshes/prop1.STL" />
      </geometry>
      <material
        name="">
        <color
          rgba="0 0 0 1" />
      </material>
    </visual>
    <collision>
      <origin
        xyz="0 0 0"
        rpy="0 0 0" />
      <geometry>
        <mesh
          filename="package://f550_rd_basic_v1/meshes/prop1.STL" />
      </geometry>
    </collision>
  </link>
  <joint
    name="p1"
    type="continuous">
    <origin
      xyz="0.159099025766974 -0.0820250109897306 0.0597327877613558"
      rpy="0 0 -1.92059574803774" />
    <parent
      link="wing1" />
    <child
      link="prop1" />
    <axis
      xyz="0 0 1" />
  </joint>
  <link
    name="wing2">
    <inertial>
      <origin
        xyz="0.12144 0.12144 0.038426"
        rpy="0 0 0" />
      <mass
        value="0.11819" />
      <inertia
        ixx="0.00031708"
        ixy="-0.00028166"
        ixz="-4.3423E-05"
        iyy="0.00031709"
        iyz="-4.3424E-05"
        izz="0.00057917" />
    </inertial>
    <visual>
      <origin
        xyz="0 0 0"
        rpy="0 0 0" />
      <geometry>
        <mesh
          filename="package://f550_rd_basic_v1/meshes/wing2.STL" />
      </geometry>
      <material
        name="">
        <color
          rgba="0.75294 0.75294 0.75294 1" />
      </material>
    </visual>
    <collision>
      <origin
        xyz="0 0 0"
        rpy="0 0 0" />
      <geometry>
        <mesh
          filename="package://f550_rd_basic_v1/meshes/wing2.STL" />
      </geometry>
    </collision>
  </link>
  <joint
    name="w2"
    type="fixed">
    <origin
      xyz="0.0479230484541336 0 -0.0402465423967926"
      rpy="-4.32963728535971E-17 -4.32963728535965E-17 -0.785398163397441" />
    <parent
      link="base_link" />
    <child
      link="wing2" />
    <axis
      xyz="0 0 0" />
  </joint>
  <link
    name="prop2">
    <inertial>
      <origin
        xyz="-6.06903996613894E-07 2.09895339214388E-08 0.00785142091305206"
        rpy="0 0 0" />
      <mass
        value="0.00919102949836486" />
      <inertia
        ixx="3.00756495521516E-07"
        ixy="-1.44553112000028E-07"
        ixz="7.8392478172389E-11"
        iyy="3.41061137513193E-05"
        iyz="-3.56044237665579E-12"
        izz="3.43204927897154E-05" />
    </inertial>
    <visual>
      <origin
        xyz="0 0 0"
        rpy="0 0 0" />
      <geometry>
        <mesh
          filename="package://f550_rd_basic_v1/meshes/prop2.STL" />
      </geometry>
      <material
        name="">
        <color
          rgba="0 0 0 1" />
      </material>
    </visual>
    <collision>
      <origin
        xyz="0 0 0"
        rpy="0 0 0" />
      <geometry>
        <mesh
          filename="package://f550_rd_basic_v1/meshes/prop2.STL" />
      </geometry>
    </collision>
  </link>
  <joint
    name="p2"
    type="continuous">
    <origin
      xyz="0.159099025766667 0.159099025766664 0.0597327877613558"
      rpy="0 0 0.785398163397441" />
    <parent
      link="wing2" />
    <child
      link="prop2" />
    <axis
      xyz="0 0 1" />
  </joint>
  <link
    name="wing3">
    <inertial>
      <origin
        xyz="0.12144 -0.11968 0.038426"
        rpy="0 0 0" />
      <mass
        value="0.11819" />
      <inertia
        ixx="0.0003171"
        ixy="-0.00028167"
        ixz="-4.3423E-05"
        iyy="0.00031709"
        iyz="-4.3436E-05"
        izz="0.0005792" />
    </inertial>
    <visual>
      <origin
        xyz="0 0 0"
        rpy="0 0 0" />
      <geometry>
        <mesh
          filename="package://f550_rd_basic_v1/meshes/wing3.STL" />
      </geometry>
      <material
        name="">
        <color
          rgba="0.75294 0.75294 0.75294 1" />
      </material>
    </visual>
    <collision>
      <origin
        xyz="0 0 0"
        rpy="0 0 0" />
      <geometry>
        <mesh
          filename="package://f550_rd_basic_v1/meshes/wing3.STL" />
      </geometry>
    </collision>
  </link>
  <joint
    name="w3"
    type="fixed">
    <origin
      xyz="0.258425755265039 -0.104255099483012 -0.0402465423967927"
      rpy="-1.37193120842531E-15 -5.91439452097321E-17 -1.83259571459404" />
    <parent
      link="base_link" />
    <child
      link="wing3" />
    <axis
      xyz="0 0 0" />
  </joint>
  <link
    name="prop3">
    <inertial>
      <origin
        xyz="6.73302480991289E-08 3.11284387155553E-10 0.00785252943141168"
        rpy="0 0 0" />
      <mass
        value="0.00918371361845548" />
      <inertia
        ixx="3.00899363978341E-07"
        ixy="1.50416409146065E-07"
        ixz="5.75790647060304E-12"
        iyy="3.40245137086448E-05"
        iyz="3.97946365003819E-13"
        izz="3.42389904138933E-05" />
    </inertial>
    <visual>
      <origin
        xyz="0 0 0"
        rpy="0 0 0" />
      <geometry>
        <mesh
          filename="package://f550_rd_basic_v1/meshes/prop3.STL" />
      </geometry>
      <material
        name="">
        <color
          rgba="0 0 0 1" />
      </material>
    </visual>
    <collision>
      <origin
        xyz="0 0 0"
        rpy="0 0 0" />
      <geometry>
        <mesh
          filename="package://f550_rd_basic_v1/meshes/prop3.STL" />
      </geometry>
    </collision>
  </link>
  <joint
    name="p3"
    type="continuous">
    <origin
      xyz="0.159099025766974 -0.0820250109897308 0.0597327877613557"
      rpy="-1.22388836600251E-17 -1.34049136553275E-15 1.83259571459404" />
    <parent
      link="wing3" />
    <child
      link="prop3" />
    <axis
      xyz="0 0 1" />
  </joint>
  <link
    name="wing4">
    <inertial>
      <origin
        xyz="0.12144 0.12144 0.038426"
        rpy="0 0 0" />
      <mass
        value="0.11819" />
      <inertia
        ixx="0.00031708"
        ixy="-0.00028166"
        ixz="-4.3423E-05"
        iyy="0.00031709"
        iyz="-4.3424E-05"
        izz="0.00057917" />
    </inertial>
    <visual>
      <origin
        xyz="0 0 0"
        rpy="0 0 0" />
      <geometry>
        <mesh
          filename="package://f550_rd_basic_v1/meshes/wing4.STL" />
      </geometry>
      <material
        name="">
        <color
          rgba="0.594 0.411 0.388 1" />
      </material>
    </visual>
    <collision>
      <origin
        xyz="0 0 0"
        rpy="0 0 0" />
      <geometry>
        <mesh
          filename="package://f550_rd_basic_v1/meshes/wing4.STL" />
      </geometry>
    </collision>
  </link>
  <joint
    name="w4"
    type="fixed">
    <origin
      xyz="-0.0229899261393952 0.043307086335355 -0.0402465423967929"
      rpy="-1.58475723561386E-17 5.91439452097364E-17 1.30899693899576" />
    <parent
      link="base_link" />
    <child
      link="wing4" />
    <axis
      xyz="0 0 0" />
  </joint>
  <link
    name="prop4">
    <inertial>
      <origin
        xyz="-6.17499109040187E-07 1.69915435055401E-08 0.00785142024101908"
        rpy="0 0 0" />
      <mass
        value="0.00919100505825974" />
      <inertia
        ixx="3.00756413802507E-07"
        ixy="-1.44552620063001E-07"
        ixz="7.84558787770827E-11"
        iyy="3.41061243643494E-05"
        iyz="-3.57114302807906E-12"
        izz="3.43205032762088E-05" />
    </inertial>
    <visual>
      <origin
        xyz="0 0 0"
        rpy="0 0 0" />
      <geometry>
        <mesh
          filename="package://f550_rd_basic_v1/meshes/prop4.STL" />
      </geometry>
      <material
        name="">
        <color
          rgba="0.752941176470588 0 0 1" />
      </material>
    </visual>
    <collision>
      <origin
        xyz="0 0 0"
        rpy="0 0 0" />
      <geometry>
        <mesh
          filename="package://f550_rd_basic_v1/meshes/prop4.STL" />
      </geometry>
    </collision>
  </link>
  <joint
    name="p4"
    type="continuous">
    <origin
      xyz="0.159099025766974 0.159099025766357 0.0597327877613558"
      rpy="0 0 -1.30899693899576" />
    <parent
      link="wing4" />
    <child
      link="prop4" />
    <axis
      xyz="0 0 1" />
  </joint>
  <link
    name="wing5">
    <inertial>
      <origin
        xyz="0.12144 0.12144 0.038426"
        rpy="0 0 0" />
      <mass
        value="0.11819" />
      <inertia
        ixx="0.00031708"
        ixy="-0.00028166"
        ixz="-4.3423E-05"
        iyy="0.00031709"
        iyz="-4.3424E-05"
        izz="0.00057917" />
    </inertial>
    <visual>
      <origin
        xyz="0 0 0"
        rpy="0 0 0" />
      <geometry>
        <mesh
          filename="package://f550_rd_basic_v1/meshes/wing5.STL" />
      </geometry>
      <material
        name="">
        <color
          rgba="0.75294 0.75294 0.75294 1" />
      </material>
    </visual>
    <collision>
      <origin
        xyz="0 0 0"
        rpy="0 0 0" />
      <geometry>
        <mesh
          filename="package://f550_rd_basic_v1/meshes/wing5.STL" />
      </geometry>
    </collision>
  </link>
  <joint
    name="w5"
    type="fixed">
    <origin
      xyz="-0.0251440484568347 -0.0420634032355138 -0.0402465423967926"
      rpy="5.9143945209736E-17 -7.09736962746862E-16 -2.87979326579064" />
    <parent
      link="base_link" />
    <child
      link="wing5" />
    <axis
      xyz="0 0 0" />
  </joint>
  <link
    name="prop5">
    <inertial>
      <origin
        xyz="-6.95645356985075E-07 1.7149377112835E-08 0.00785143154723994"
        rpy="0 0 0" />
      <mass
        value="0.00919099480486216" />
      <inertia
        ixx="3.00752111229346E-07"
        ixy="-1.44552434580939E-07"
        ixz="7.07667846431983E-11"
        iyy="3.41060666318963E-05"
        iyz="-3.03783252474656E-12"
        izz="3.43204418856938E-05" />
    </inertial>
    <visual>
      <origin
        xyz="0 0 0"
        rpy="0 0 0" />
      <geometry>
        <mesh
          filename="package://f550_rd_basic_v1/meshes/prop5.STL" />
      </geometry>
      <material
        name="">
        <color
          rgba="0 0 0 1" />
      </material>
    </visual>
    <collision>
      <origin
        xyz="0 0 0"
        rpy="0 0 0" />
      <geometry>
        <mesh
          filename="package://f550_rd_basic_v1/meshes/prop5.STL" />
      </geometry>
    </collision>
  </link>
  <joint
    name="p5"
    type="continuous">
    <origin
      xyz="0.159099025766974 0.159099025766357 0.0597327877613557"
      rpy="-9.91037528426906E-17 -6.86775751078402E-16 -2.99827901567927" />
    <parent
      link="wing5" />
    <child
      link="prop5" />
    <axis
      xyz="0 0 1" />
  </joint>
  <link
    name="wing6">
    <inertial>
      <origin
        xyz="0.12144 -0.11968 0.038426"
        rpy="0 0 0" />
      <mass
        value="0.11819" />
      <inertia
        ixx="0.0003171"
        ixy="-0.00028167"
        ixz="-4.3423E-05"
        iyy="0.00031709"
        iyz="-4.3436E-05"
        izz="0.0005792" />
    </inertial>
    <visual>
      <origin
        xyz="0 0 0"
        rpy="0 0 0" />
      <geometry>
        <mesh
          filename="package://f550_rd_basic_v1/meshes/wing6.STL" />
      </geometry>
      <material
        name="">
        <color
          rgba="0.594 0.411 0.388 1" />
      </material>
    </visual>
    <collision>
      <origin
        xyz="0 0 0"
        rpy="0 0 0" />
      <geometry>
        <mesh
          filename="package://f550_rd_basic_v1/meshes/wing6.STL" />
      </geometry>
    </collision>
  </link>
  <joint
    name="w6"
    type="fixed">
    <origin
      xyz="-0.0391362391482408 0.2748090405283 -0.0402465423967925"
      rpy="-5.9143945209736E-17 1.58475723561399E-17 0.261799387799158" />
    <parent
      link="base_link" />
    <child
      link="wing6" />
    <axis
      xyz="0 0 0" />
  </joint>
  <link
    name="prop6">
    <inertial>
      <origin
        xyz="1.4102E-06 -7.3846E-08 0.0078525"
        rpy="0 0 0" />
      <mass
        value="0.0091836" />
      <inertia
        ixx="3.0089E-07"
        ixy="1.5035E-07"
        ixz="6.9021E-12"
        iyy="3.4023E-05"
        iyz="-3.445E-13"
        izz="3.4238E-05" />
    </inertial>
    <visual>
      <origin
        xyz="0 0 0"
        rpy="0 0 0" />
      <geometry>
        <mesh
          filename="package://f550_rd_basic_v1/meshes/prop6.STL" />
      </geometry>
      <material
        name="">
        <color
          rgba="0.50196 0 0 1" />
      </material>
    </visual>
    <collision>
      <origin
        xyz="0 0 0"
        rpy="0 0 0" />
      <geometry>
        <mesh
          filename="package://f550_rd_basic_v1/meshes/prop6.STL" />
      </geometry>
    </collision>
  </link>
  <joint
    name="p6"
    type="continuous">
    <origin
      xyz="0.159099025766974 -0.0820250109897306 0.0597327877613558"
      rpy="0 0 -2.70619330605538" />
    <parent
      link="wing6" />
    <child
      link="prop6" />
    <axis
      xyz="0 0 1" />
  </joint>
  <link
    name="fcu_px2">
    <inertial>
      <origin
        xyz="0.002093 0.00024832 -0.0059171"
        rpy="0 0 0" />
      <mass
        value="0.25" />
      <inertia
        ixx="7.9881E-06"
        ixy="1.4254E-07"
        ixz="9.5267E-07"
        iyy="3.4253E-05"
        iyz="-1.0276E-08"
        izz="4.0844E-05" />
    </inertial>
    <visual>
      <origin
        xyz="0 0 0"
        rpy="0 0 0" />
      <geometry>
        <mesh
          filename="package://f550_rd_basic_v1/meshes/fcu_px2.STL" />
      </geometry>
      <material
        name="">
        <color
          rgba="0.79216 0.81961 0.93333 1" />
      </material>
    </visual>
    <collision>
      <origin
        xyz="0 0 0"
        rpy="0 0 0" />
      <geometry>
        <mesh
          filename="package://f550_rd_basic_v1/meshes/fcu_px2.STL" />
      </geometry>
    </collision>
  </link>
  <joint
    name="fcu_fix"
    type="fixed">
    <origin
      xyz="0 0 -0.0394965423967926"
      rpy="3.14159265358979 6.12303176911189E-17 1.5707963267949" />
    <parent
      link="base_link" />
    <child
      link="fcu_px2" />
    <axis
      xyz="0 0 0" />
  </joint>
  <link
    name="gps_here">
    <inertial>
      <origin
        xyz="-1.3121E-06 -6.68E-05 0.0084082"
        rpy="0 0 0" />
      <mass
        value="0.0" />
      <inertia
        ixx="2.9868E-05"
        ixy="-1.0411E-10"
        ixz="5.0539E-11"
        iyy="2.9724E-05"
        iyz="4.7726E-08"
        izz="5.5952E-05" />
    </inertial>
    <visual>
      <origin
        xyz="0 0 0"
        rpy="0 0 0" />
      <geometry>
        <mesh
          filename="package://f550_rd_basic_v1/meshes/gps_here.STL" />
      </geometry>
      <material
        name="">
        <color
          rgba="0.3 0.3 0.3 1" />
      </material>
    </visual>
    <collision>
      <origin
        xyz="0 0 0"
        rpy="0 0 0" />
      <geometry>
        <mesh
          filename="package://f550_rd_basic_v1/meshes/gps_here.STL" />
      </geometry>
    </collision>
  </link>
  <joint
    name="fcu2gps_fix"
    type="fixed">
    <origin
      xyz="0.00198507835763108 -0.145 -0.0379965423967927"
      rpy="3.14159265358979 -1.3010426069826E-16 -1.5707963267949" />
    <parent
      link="fcu_px2" />
    <child
      link="gps_here" />
    <axis
      xyz="0 0 0" />
  </joint>
  <link
    name="lrf_horizontal">
    <inertial>
      <origin
        xyz="2.3187E-06 -0.029952 0.0217"
        rpy="0 0 0" />
      <mass
        value="0.1926" />
      <inertia
        ixx="0.00023701"
        ixy="-5.7242E-08"
        ixz="6.8532E-09"
        iyy="0.00023618"
        iyz="-2.9987E-06"
        izz="0.00014751" />
    </inertial>
    <visual>
      <origin
        xyz="0 0 0"
        rpy="0 0 0" />
      <geometry>
        <mesh
          filename="package://f550_rd_basic_v1/meshes/lrf_horizontal.STL" />
      </geometry>
      <material
        name="">
        <color
          rgba="0.176 0.176 0.275 1" />
      </material>
    </visual>
    <collision>
      <origin
        xyz="0 0 0"
        rpy="0 0 0" />
      <geometry>
        <mesh
          filename="package://f550_rd_basic_v1/meshes/lrf_horizontal.STL" />
      </geometry>
    </collision>
  </link>
  <joint
    name="lrf_fix"
    type="fixed">
    <origin
      xyz="0 -0.014180598689214 0.026"
      rpy="-6.12303176911189E-17 0 0" />
    <parent
      link="base_link" />
    <child
      link="lrf_horizontal" />
    <axis
      xyz="0 -1 0" />
  </joint>
  <link
    name="odroid_xu4">
    <inertial>
      <origin
        xyz="0.0057413 0.00030748 -0.0052843"
        rpy="0 0 0" />
      <mass
        value="0.08" />
      <inertia
        ixx="4.4834E-06"
        ixy="3.2726E-07"
        ixz="1.7419E-07"
        iyy="6.5755E-06"
        iyz="1.4639E-08"
        izz="1.0308E-05" />
    </inertial>
    <visual>
      <origin
        xyz="0 0 0"
        rpy="0 0 0" />
      <geometry>
        <mesh
          filename="package://f550_rd_basic_v1/meshes/odroid_xu4.STL" />
      </geometry>
      <material
        name="">
        <color
          rgba="0 0.1 0.45 1" />
      </material>
    </visual>
    <collision>
      <origin
        xyz="0 0 0"
        rpy="0 0 0" />
      <geometry>
        <mesh
          filename="package://f550_rd_basic_v1/meshes/odroid_xu4.STL" />
      </geometry>
    </collision>
  </link>
  <joint
    name="base2odroid_fix"
    type="fixed">
    <origin
      xyz="0 0.0265 0.038"
      rpy="3.14159265358979 -6.12303176911189E-17 -1.5707963267949" />
    <parent
      link="base_link" />
    <child
      link="odroid_xu4" />
    <axis
      xyz="0 0 0" />
  </joint>
</robot>
