<?xml version="1.0" ?>
<sdf version='1.6'>
  <model name='f550_rd_basic_2'>
    <link name='base_link'>
      <pose frame=''>0 0 0 0 0 0</pose>
      <inertial>
        <pose frame=''>0 0 0 0 0 0</pose>
        <mass>1.50</mass>
        <inertia>
          <ixx>0.0213982</ixx>
          <ixy>3.82398e-05</ixy>
          <ixz>2.62527e-05</ixz>
          <iyy>0.021956</iyy>
          <iyz>0.000340426</iyz>
          <izz>0.0398396</izz>
        </inertia>
      </inertial>
      <collision name='base_link_collision'>
        <pose frame=''>0 0 0 0 0 0</pose>
        <geometry>
          <mesh>
            <scale>1 1 1</scale>
            <uri>model://f550_rd_basic_v1/meshes/base_link.STL</uri>
          </mesh>
        </geometry>
      </collision>
      <collision name='base_link_fixed_joint_lump__odroid_xu4_collision_1'>
        <pose frame=''>0 0.0265 0.038 3.14159 -0 -1.5708</pose>
        <geometry>
          <mesh>
            <scale>1 1 1</scale>
            <uri>model://f550_rd_basic_v1/meshes/odroid_xu4.STL</uri>
          </mesh>
        </geometry>
      </collision>
      <collision name='base_link_fixed_joint_lump__fcu_px2_collision_2'>
        <pose frame=''>0 0 -0.039497 3.14159 0 1.5708</pose>
        <geometry>
          <mesh>
            <scale>1 1 1</scale>
            <uri>model://f550_rd_basic_v1/meshes/fcu_px2.STL</uri>
          </mesh>
        </geometry>
      </collision>
      <collision name='base_link_fixed_joint_lump__gps_here_collision_3'>
        <pose frame=''>-0.145 0.001985 -0.0015 -0 0 -3.14159</pose>
        <geometry>
          <mesh>
            <scale>1 1 1</scale>
            <uri>model://f550_rd_basic_v1/meshes/gps_here.STL</uri>
          </mesh>
        </geometry>
      </collision>
      <collision name='base_link_fixed_joint_lump__lrf_horizontal_collision_4'>
        <pose frame=''>0 -0.014181 0.026 -0 0 0</pose>
        <geometry>
          <mesh>
            <scale>1 1 1</scale>
            <uri>model://f550_rd_basic_v1/meshes/lrf_horizontal.STL</uri>
          </mesh>
        </geometry>
      </collision>
      <collision name='base_link_fixed_joint_lump__wing1_collision_5'>
        <pose frame=''>-0.2195 -0.1705 -0.040247 0 0 2.35619</pose>
        <geometry>
          <mesh>
            <scale>1 1 1</scale>
            <uri>model://f550_rd_basic_v1/meshes/wing1.STL</uri>
          </mesh>
        </geometry>
      </collision>
      <collision name='base_link_fixed_joint_lump__wing2_collision_6'>
        <pose frame=''>0.047923 0 -0.040247 -0 -0 -0.785398</pose>
        <geometry>
          <mesh>
            <scale>1 1 1</scale>
            <uri>model://f550_rd_basic_v1/meshes/wing2.STL</uri>
          </mesh>
        </geometry>
      </collision>
      <collision name='base_link_fixed_joint_lump__wing3_collision_7'>
        <pose frame=''>0.258426 -0.104255 -0.040247 -0 -0 -1.8326</pose>
        <geometry>
          <mesh>
            <scale>1 1 1</scale>
            <uri>model://f550_rd_basic_v1/meshes/wing3.STL</uri>
          </mesh>
        </geometry>
      </collision>
      <collision name='base_link_fixed_joint_lump__wing4_collision_8'>
        <pose frame=''>-0.02299 0.043307 -0.040247 -0 0 1.309</pose>
        <geometry>
          <mesh>
            <scale>1 1 1</scale>
            <uri>model://f550_rd_basic_v1/meshes/wing4.STL</uri>
          </mesh>
        </geometry>
      </collision>
      <collision name='base_link_fixed_joint_lump__wing5_collision_9'>
        <pose frame=''>-0.025144 -0.042063 -0.040247 0 -0 -2.87979</pose>
        <geometry>
          <mesh>
            <scale>1 1 1</scale>
            <uri>model://f550_rd_basic_v1/meshes/wing5.STL</uri>
          </mesh>
        </geometry>
      </collision>
      <collision name='base_link_fixed_joint_lump__wing6_collision_10'>
        <pose frame=''>-0.039136 0.274809 -0.040247 -0 0 0.261799</pose>
        <geometry>
          <mesh>
            <scale>1 1 1</scale>
            <uri>model://f550_rd_basic_v1/meshes/wing6.STL</uri>
          </mesh>
        </geometry>
      </collision>
      <visual name='base_link_visual'>
        <pose frame=''>0 0 0 0 -0 0</pose>
        <geometry>
          <mesh>
            <scale>1 1 1</scale>
            <uri>model://f550_rd_basic_v1/meshes/base_link.STL</uri>
          </mesh>
        </geometry>
        <material>
          <script>
            <name>Gazebo/Black</name>
            <uri>file://media/materials/scripts/gazebo.material</uri>
          </script>
        </material>
      </visual>
      <visual name='base_link_fixed_joint_lump__odroid_xu4_visual_1'>
        <pose frame=''>0 0.0265 0.038 3.14159 -0 -1.5708</pose>
        <geometry>
          <mesh>
            <scale>1 1 1</scale>
            <uri>model://f550_rd_basic_v1/meshes/odroid_xu4.STL</uri>
          </mesh>
        </geometry>
        <material>
          <script>
            <name>Gazebo/DarkGrey</name>
            <uri>file://media/materials/scripts/gazebo.material</uri>
          </script>
        </material>
      </visual>
      <visual name='base_link_fixed_joint_lump__fcu_px2_visual_2'>
        <pose frame=''>0 0 -0.039497 3.14159 0 1.5708</pose>
        <geometry>
          <mesh>
            <scale>1 1 1</scale>
            <uri>model://f550_rd_basic_v1/meshes/fcu_px2.STL</uri>
          </mesh>
        </geometry>
        <material>
          <script>
            <name>Gazebo/FlatBlack</name>
            <uri>file://media/materials/scripts/gazebo.material</uri>
          </script>
        </material>
      </visual>
      <visual name='base_link_fixed_joint_lump__gps_here_visual_3'>
        <pose frame=''>-0.145 0.001985 -0.0015 -0 0 -3.14159</pose>
        <geometry>
          <mesh>
            <scale>1 1 1</scale>
            <uri>model://f550_rd_basic_v1/meshes/gps_here.STL</uri>
          </mesh>
        </geometry>
        <material>
          <script>
            <name>Gazebo/DarkGrey</name>
            <uri>file://media/materials/scripts/gazebo.material</uri>
          </script>
        </material>
      </visual>
      <visual name='base_link_fixed_joint_lump__lrf_horizontal_visual_4'>
        <pose frame=''>0 -0.014181 0.026 -0 0 0</pose>
        <geometry>
          <mesh>
            <scale>1 1 1</scale>
            <uri>model://f550_rd_basic_v1/meshes/lrf_horizontal.STL</uri>
          </mesh>
        </geometry>
        <material>
          <script>
            <name>Gazebo/DarkGrey</name>
            <uri>file://media/materials/scripts/gazebo.material</uri>
          </script>
        </material>
      </visual>
      <visual name='base_link_fixed_joint_lump__wing1_visual_5'>
        <pose frame=''>-0.2195 -0.1705 -0.040247 0 0 2.35619</pose>
        <geometry>
          <mesh>
            <scale>1 1 1</scale>
            <uri>model://f550_rd_basic_v1/meshes/wing1.STL</uri>
          </mesh>
        </geometry>
        <material>
          <script>
            <name>Gazebo/White</name>
            <uri>file://media/materials/scripts/gazebo.material</uri>
          </script>
        </material>
      </visual>
      <visual name='base_link_fixed_joint_lump__wing2_visual_6'>
        <pose frame=''>0.047923 0 -0.040247 -0 -0 -0.785398</pose>
        <geometry>
          <mesh>
            <scale>1 1 1</scale>
            <uri>model://f550_rd_basic_v1/meshes/wing2.STL</uri>
          </mesh>
        </geometry>
        <material>
          <script>
            <name>Gazebo/White</name>
            <uri>file://media/materials/scripts/gazebo.material</uri>
          </script>
        </material>
      </visual>
      <visual name='base_link_fixed_joint_lump__wing3_visual_7'>
        <pose frame=''>0.258426 -0.104255 -0.040247 -0 -0 -1.8326</pose>
        <geometry>
          <mesh>
            <scale>1 1 1</scale>
            <uri>model://f550_rd_basic_v1/meshes/wing3.STL</uri>
          </mesh>
        </geometry>
        <material>
          <script>
            <name>Gazebo/White</name>
            <uri>file://media/materials/scripts/gazebo.material</uri>
          </script>
        </material>
      </visual>
      <visual name='base_link_fixed_joint_lump__wing4_visual_8'>
        <pose frame=''>-0.02299 0.043307 -0.040247 -0 0 1.309</pose>
        <geometry>
          <mesh>
            <scale>1 1 1</scale>
            <uri>model://f550_rd_basic_v1/meshes/wing4.STL</uri>
          </mesh>
        </geometry>
        <material>
          <script>
            <name>Gazebo/Red</name>
            <uri>file://media/materials/scripts/gazebo.material</uri>
          </script>
        </material>
      </visual>
      <visual name='base_link_fixed_joint_lump__wing5_visual_9'>
        <pose frame=''>-0.025144 -0.042063 -0.040247 0 -0 -2.87979</pose>
        <geometry>
          <mesh>
            <scale>1 1 1</scale>
            <uri>model://f550_rd_basic_v1/meshes/wing5.STL</uri>
          </mesh>
        </geometry>
]        <material>
          <script>
            <name>Gazebo/White</name>
            <uri>file://media/materials/scripts/gazebo.material</uri>
          </script>
        </material>
      </visual>
      <visual name='base_link_fixed_joint_lump__wing6_visual_10'>
        <pose frame=''>-0.039136 0.274809 -0.040247 -0 0 0.261799</pose>
        <geometry>
          <mesh>
            <scale>1 1 1</scale>
            <uri>model://f550_rd_basic_v1/meshes/wing6.STL</uri>
          </mesh>
        </geometry>
        <material>
          <script>
            <name>Gazebo/Red</name>
            <uri>file://media/materials/scripts/gazebo.material</uri>
          </script>
        </material>
      </visual>
    </link>
    <link name='/imu_link'>
      <pose frame=''>0 0 0 0 -0 0</pose>
      <inertial>
        <pose frame=''>0 0 0 0 -0 0</pose>
        <mass>0.015</mass>
        <inertia>
          <ixx>1e-05</ixx>
          <ixy>0</ixy>
          <ixz>0</ixz>
          <iyy>1e-05</iyy>
          <iyz>0</iyz>
          <izz>1e-05</izz>
        </inertia>
      </inertial>
    </link>
    <joint name='/imu_joint' type='revolute'>
      <child>/imu_link</child>
      <parent>base_link</parent>
      <axis>
        <xyz>0.01 -0.01 0.01</xyz>
        <limit>
          <lower>0</lower>
          <upper>0</upper>
          <effort>0</effort>
          <velocity>0</velocity>
        </limit>
        <dynamics>
          <spring_reference>0</spring_reference>
          <spring_stiffness>0</spring_stiffness>
        </dynamics>
        <use_parent_model_frame>1</use_parent_model_frame>
      </axis>
    </joint>

    <link name='prop1'>
      <pose frame=''>-0.274 -0 0.019486 -0 0 0.435599</pose>
      <inertial>
        <pose frame=''>0 0 0.007853 0 -0 0</pose>
        <mass>0.0091837</mass>
        <inertia>
          <ixx>3.009e-07</ixx>
          <ixy>1.5042e-07</ixy>
          <ixz>5.8166e-13</ixz>
          <iyy>3.4024e-05</iyy>
          <iyz>-7.7721e-14</iyz>
          <izz>3.4239e-05</izz>
        </inertia>
      </inertial>
      <collision name='prop1_collision'>
        <pose frame=''>0 0 0 0 -0 0</pose>
        <geometry>
          <mesh>
            <scale>1 1 1</scale>
            <uri>model://f550_rd_basic_v1/meshes/prop1.STL</uri>
          </mesh>
        </geometry>
      </collision>
      <visual name='prop1_visual'>
        <pose frame=''>0 0 0 0 -0 0</pose>
        <geometry>
          <mesh>
            <scale>1 1 1</scale>
            <uri>model://f550_rd_basic_v1/meshes/prop1.STL</uri>
          </mesh>
        </geometry>
        <material>
          <script>
            <name>Gazebo/Black</name>
            <uri>file://media/materials/scripts/gazebo.material</uri>
          </script>
        </material>
      </visual>
    </link>
    <joint name='p1' type='revolute'>
      <child>prop1</child>
      <parent>base_link</parent>
      <axis>
        <xyz>0 0 1</xyz>
        <limit>
          <lower>-1e+16</lower>
          <upper>1e+16</upper>
        </limit>
        <dynamics>
          <spring_reference>0</spring_reference>
          <spring_stiffness>0</spring_stiffness>
        </dynamics>
        <use_parent_model_frame>1</use_parent_model_frame>
      </axis>
    </joint>
    <link name='prop2'>
      <pose frame=''>0.272923 -0 0.019486 -0 -0 0</pose>
      <inertial>
        <pose frame=''>-1e-06 0 0.007851 0 -0 0</pose>
        <mass>0.0091837</mass>
        <inertia>
          <ixx>3.009e-07</ixx>
          <ixy>1.5042e-07</ixy>
          <ixz>5.8166e-13</ixz>
          <iyy>3.4024e-05</iyy>
          <iyz>-7.7721e-14</iyz>
          <izz>3.4239e-05</izz>
        </inertia>
      </inertial>
      <collision name='prop2_collision'>
        <pose frame=''>0 0 0 0 -0 0</pose>
        <geometry>
          <mesh>
            <scale>1 1 1</scale>
            <uri>model://f550_rd_basic_v1/meshes/prop2.STL</uri>
          </mesh>
        </geometry>
      </collision>
      <visual name='prop2_visual'>
        <pose frame=''>0 0 0 0 -0 0</pose>
        <geometry>
          <mesh>
            <scale>1 1 1</scale>
            <uri>model://f550_rd_basic_v1/meshes/prop2.STL</uri>
          </mesh>
        </geometry>
        <material>
          <script>
            <name>Gazebo/Black</name>
            <uri>file://media/materials/scripts/gazebo.material</uri>
          </script>
        </material>
      </visual>
    </link>
    <joint name='p2' type='revolute'>
      <child>prop2</child>
      <parent>base_link</parent>
      <axis>
        <xyz>0 0 1</xyz>
        <limit>
          <lower>-1e+16</lower>
          <upper>1e+16</upper>
        </limit>
        <dynamics>
          <spring_reference>0</spring_reference>
          <spring_stiffness>0</spring_stiffness>
        </dynamics>
        <use_parent_model_frame>1</use_parent_model_frame>
      </axis>
    </joint>
    <link name='prop3'>
      <pose frame=''>0.138018 -0.236703 0.019486 0 0 0</pose>
      <inertial>
        <pose frame=''>0 0 0.007853 0 -0 0</pose>
        <mass>0.0091837</mass>
        <inertia>
          <ixx>3.009e-07</ixx>
          <ixy>1.5042e-07</ixy>
          <ixz>5.8166e-13</ixz>
          <iyy>3.4024e-05</iyy>
          <iyz>-7.7721e-14</iyz>
          <izz>3.4239e-05</izz>
        </inertia>
      </inertial>
      <collision name='prop3_collision'>
        <pose frame=''>0 0 0 0 -0 0</pose>
        <geometry>
          <mesh>
            <scale>1 1 1</scale>
            <uri>model://f550_rd_basic_v1/meshes/prop3.STL</uri>
          </mesh>
        </geometry>
      </collision>
      <visual name='prop3_visual'>
        <pose frame=''>0 0 0 0 -0 0</pose>
        <geometry>
          <mesh>
            <scale>1 1 1</scale>
            <uri>model://f550_rd_basic_v1/meshes/prop3.STL</uri>
          </mesh>
        </geometry>
        <material>
          <script>
            <name>Gazebo/Black</name>
            <uri>file://media/materials/scripts/gazebo.material</uri>
          </script>
        </material>
      </visual>
    </link>
    <joint name='p3' type='revolute'>
      <child>prop3</child>
      <parent>base_link</parent>
      <axis>
        <xyz>0 0 1</xyz>
        <limit>
          <lower>-1e+16</lower>
          <upper>1e+16</upper>
        </limit>
        <dynamics>
          <spring_reference>0</spring_reference>
          <spring_stiffness>0</spring_stiffness>
        </dynamics>
        <use_parent_model_frame>1</use_parent_model_frame>
      </axis>
    </joint>
    <link name='prop4'>
      <pose frame=''>-0.13549 0.238163 0.019486 -0 0 -0</pose>
      <inertial>
        <pose frame=''>-1e-06 0 0.007851 0 -0 0</pose>
        <mass>0.0091837</mass>
        <inertia>
          <ixx>3.009e-07</ixx>
          <ixy>1.5042e-07</ixy>
          <ixz>5.8166e-13</ixz>
          <iyy>3.4024e-05</iyy>
          <iyz>-7.7721e-14</iyz>
          <izz>3.4239e-05</izz>
        </inertia>
      </inertial>
      <collision name='prop4_collision'>
        <pose frame=''>0 0 0 0 -0 0</pose>
        <geometry>
          <mesh>
            <scale>1 1 1</scale>
            <uri>model://f550_rd_basic_v1/meshes/prop4.STL</uri>
          </mesh>
        </geometry>
      </collision>
      <visual name='prop4_visual'>
        <pose frame=''>0 0 0 0 -0 0</pose>
        <geometry>
          <mesh>
            <scale>1 1 1</scale>
            <uri>model://f550_rd_basic_v1/meshes/prop4.STL</uri>
          </mesh>
        </geometry>
        <material>
          <script>
            <name>Gazebo/Orange</name>
            <uri>file://media/materials/scripts/gazebo.material</uri>
          </script>
        </material>
      </visual>
    </link>
    <joint name='p4' type='revolute'>
      <child>prop4</child>
      <parent>base_link</parent>
      <axis>
        <xyz>0 0 1</xyz>
        <limit>
          <lower>-1e+16</lower>
          <upper>1e+16</upper>
        </limit>
        <dynamics>
          <spring_reference>0</spring_reference>
          <spring_stiffness>0</spring_stiffness>
        </dynamics>
        <use_parent_model_frame>1</use_parent_model_frame>
      </axis>
    </joint>
    <link name='prop5'>
      <pose frame=''>-0.137644 -0.236919 0.019486 -0 0 0.405113</pose>
      <inertial>
        <pose frame=''>-1e-06 0 0.007851 0 -0 0</pose>
        <mass>0.0091837</mass>
        <inertia>
          <ixx>3.009e-07</ixx>
          <ixy>1.5042e-07</ixy>
          <ixz>5.8166e-13</ixz>
          <iyy>3.4024e-05</iyy>
          <iyz>-7.7721e-14</iyz>
          <izz>3.4239e-05</izz>
        </inertia>
      </inertial>
      <collision name='prop5_collision'>
        <pose frame=''>0 0 0 0 -0 0</pose>
        <geometry>
          <mesh>
            <scale>1 1 1</scale>
            <uri>model://f550_rd_basic_v1/meshes/prop5.STL</uri>
          </mesh>
        </geometry>
      </collision>
      <visual name='prop5_visual'>
        <pose frame=''>0 0 0 0 -0 0</pose>
        <geometry>
          <mesh>
            <scale>1 1 1</scale>
            <uri>model://f550_rd_basic_v1/meshes/prop5.STL</uri>
          </mesh>
        </geometry>
        <material>
          <script>
            <name>Gazebo/Black</name>
            <uri>file://media/materials/scripts/gazebo.material</uri>
          </script>
        </material>
      </visual>
    </link>
    <joint name='p5' type='revolute'>
      <child>prop5</child>
      <parent>base_link</parent>
      <axis>
        <xyz>-0 0 1</xyz>
        <limit>
          <lower>-1e+16</lower>
          <upper>1e+16</upper>
        </limit>
        <dynamics>
          <spring_reference>0</spring_reference>
          <spring_stiffness>0</spring_stiffness>
        </dynamics>
        <use_parent_model_frame>1</use_parent_model_frame>
      </axis>
    </joint>
    <link name='prop6'>
      <pose frame=''>0.135771 0.236757 0.019486 0 -0 -2.44439</pose>
      <inertial>
        <pose frame=''>1e-06 -0 0.007853 0 -0 0</pose>
        <mass>0.0091837</mass>
        <inertia>
          <ixx>3.009e-07</ixx>
          <ixy>1.5042e-07</ixy>
          <ixz>5.8166e-13</ixz>
          <iyy>3.4024e-05</iyy>
          <iyz>-7.7721e-14</iyz>
          <izz>3.4239e-05</izz>
        </inertia>
      </inertial>
      <collision name='prop6_collision'>
        <pose frame=''>0 0 0 0 -0 0</pose>
        <geometry>
          <mesh>
            <scale>1 1 1</scale>
            <uri>model://f550_rd_basic_v1/meshes/prop6.STL</uri>
          </mesh>
        </geometry>
      </collision>

      <visual name='prop6_visual'>
        <pose frame=''>0 0 0 0 -0 0</pose>
        <geometry>
          <mesh>
            <scale>1 1 1</scale>
            <uri>model://f550_rd_basic_v1/meshes/prop6.STL</uri>
          </mesh>
        </geometry>
        <material>
          <script>
            <name>Gazebo/Orange</name>
            <uri>file://media/materials/scripts/gazebo.material</uri>
          </script>
        </material>
      </visual>
    </link>
    <joint name='p6' type='revolute'>
      <child>prop6</child>
      <parent>base_link</parent>
      <axis>
        <xyz>0 0 1</xyz>
        <limit>
          <lower>-1e+16</lower>
          <upper>1e+16</upper>
        </limit>
        <dynamics>
          <spring_reference>0</spring_reference>
          <spring_stiffness>0</spring_stiffness>
        </dynamics>
        <use_parent_model_frame>1</use_parent_model_frame>
      </axis>
    </joint>
	<plugin name='rosbag' filename='librotors_gazebo_multirotor_base_plugin.so'>
      <robotNamespace/>
      <linkName>base_link</linkName>
      <rotorVelocitySlowdownSim>10</rotorVelocitySlowdownSim>
    </plugin>
    <plugin name='prop1_model' filename='librotors_gazebo_motor_model.so'>
      <robotNamespace/>
      <jointName>p1</jointName>
      <linkName>prop1</linkName>
      <turningDirection>cw</turningDirection>
      <timeConstantUp>0.0125</timeConstantUp>
      <timeConstantDown>0.025</timeConstantDown>
      <maxRotVelocity>1500</maxRotVelocity>
      <motorConstant>8.54858e-06</motorConstant>
      <momentConstant>0.06</momentConstant>
      <commandSubTopic>/gazebo/command/motor_speed</commandSubTopic>
      <motorNumber>0</motorNumber>
      <rotorDragCoefficient>0.000806428</rotorDragCoefficient>
      <rollingMomentCoefficient>1e-06</rollingMomentCoefficient>
      <motorSpeedPubTopic>/motor_speed/0</motorSpeedPubTopic>
      <rotorVelocitySlowdownSim>10</rotorVelocitySlowdownSim>
    </plugin>
    <plugin name='prop2_model' filename='librotors_gazebo_motor_model.so'>
      <robotNamespace/>
      <jointName>p2</jointName>
      <linkName>prop2</linkName>
      <turningDirection>ccw</turningDirection>
      <timeConstantUp>0.0125</timeConstantUp>
      <timeConstantDown>0.025</timeConstantDown>
      <maxRotVelocity>1500</maxRotVelocity>
      <motorConstant>8.54858e-06</motorConstant>
      <momentConstant>0.06</momentConstant>
      <commandSubTopic>/gazebo/command/motor_speed</commandSubTopic>
      <motorNumber>1</motorNumber>
      <rotorDragCoefficient>0.000806428</rotorDragCoefficient>
      <rollingMomentCoefficient>1e-06</rollingMomentCoefficient>
      <motorSpeedPubTopic>/motor_speed/1</motorSpeedPubTopic>
      <rotorVelocitySlowdownSim>10</rotorVelocitySlowdownSim>
    </plugin>
    <plugin name='prop3_model' filename='librotors_gazebo_motor_model.so'>
      <robotNamespace/>
      <jointName>p3</jointName>
      <linkName>prop3</linkName>
      <turningDirection>cw</turningDirection>
      <timeConstantUp>0.0125</timeConstantUp>
      <timeConstantDown>0.025</timeConstantDown>
      <maxRotVelocity>1500</maxRotVelocity>
      <motorConstant>8.54858e-06</motorConstant>
      <momentConstant>0.06</momentConstant>
      <commandSubTopic>/gazebo/command/motor_speed</commandSubTopic>
      <motorNumber>2</motorNumber>
      <rotorDragCoefficient>0.000806428</rotorDragCoefficient>
      <rollingMomentCoefficient>1e-06</rollingMomentCoefficient>
      <motorSpeedPubTopic>/motor_speed/2</motorSpeedPubTopic>
      <rotorVelocitySlowdownSim>10</rotorVelocitySlowdownSim>
    </plugin>
    <plugin name='prop4_model' filename='librotors_gazebo_motor_model.so'>
      <robotNamespace/>
      <jointName>p4</jointName>
      <linkName>prop4</linkName>
      <turningDirection>ccw</turningDirection>
      <timeConstantUp>0.0125</timeConstantUp>
      <timeConstantDown>0.025</timeConstantDown>
      <maxRotVelocity>1500</maxRotVelocity>
      <motorConstant>8.54858e-06</motorConstant>
      <momentConstant>0.06</momentConstant>
      <commandSubTopic>/gazebo/command/motor_speed</commandSubTopic>
      <motorNumber>3</motorNumber>
      <rotorDragCoefficient>0.000806428</rotorDragCoefficient>
      <rollingMomentCoefficient>1e-06</rollingMomentCoefficient>
      <motorSpeedPubTopic>/motor_speed/3</motorSpeedPubTopic>
      <rotorVelocitySlowdownSim>10</rotorVelocitySlowdownSim>
    </plugin>
   <plugin name='prop5_model' filename='librotors_gazebo_motor_model.so'>
      <robotNamespace/>
      <jointName>p5</jointName>
      <linkName>prop5</linkName>
      <turningDirection>ccw</turningDirection>
      <timeConstantUp>0.0125</timeConstantUp>
      <timeConstantDown>0.025</timeConstantDown>
      <maxRotVelocity>1500</maxRotVelocity>
      <motorConstant>8.54858e-06</motorConstant>
      <momentConstant>0.06</momentConstant>
      <commandSubTopic>/gazebo/command/motor_speed</commandSubTopic>
      <motorNumber>4</motorNumber>
      <rotorDragCoefficient>0.000806428</rotorDragCoefficient>
      <rollingMomentCoefficient>1e-06</rollingMomentCoefficient>
      <motorSpeedPubTopic>/motor_speed/4</motorSpeedPubTopic>
      <rotorVelocitySlowdownSim>10</rotorVelocitySlowdownSim>
    </plugin>
   <plugin name='prop6_model' filename='librotors_gazebo_motor_model.so'>
      <robotNamespace/>
      <jointName>p6</jointName>
      <linkName>prop6</linkName>
      <turningDirection>cw</turningDirection>
      <timeConstantUp>0.0125</timeConstantUp>
      <timeConstantDown>0.025</timeConstantDown>
      <maxRotVelocity>1500</maxRotVelocity>
      <motorConstant>8.54858e-06</motorConstant>
      <momentConstant>0.06</momentConstant>
      <commandSubTopic>/gazebo/command/motor_speed</commandSubTopic>
      <motorNumber>5</motorNumber>
      <rotorDragCoefficient>0.000806428</rotorDragCoefficient>
      <rollingMomentCoefficient>1e-06</rollingMomentCoefficient>
      <motorSpeedPubTopic>/motor_speed/5</motorSpeedPubTopic>
      <rotorVelocitySlowdownSim>10</rotorVelocitySlowdownSim>
    </plugin>
    
<!--
<link name='/gps_link'>
      <pose frame=''>-1.3121E-06 -6.68E-05 0.0084082 0 -0 0</pose>
      <inertial>
        <pose frame=''>0 0 0 0 -0 0</pose>
        <mass>0.03</mass>
        <inertia>
          <ixx>1e-05</ixx>
          <ixy>0</ixy>
          <ixz>0</ixz>
          <iyy>1e-05</iyy>
          <iyz>0</iyz>
          <izz>1e-05</izz>
        </inertia>
      </inertial>
    </link>
    <joint name='/gps_joint' type='revolute'>
      <child>/gps_link</child>
      <parent>base_link</parent>
      <axis>
        <xyz>0 0 0</xyz>
        <limit>
          <lower>0</lower>
          <upper>0</upper>
          <effort>0</effort>
          <velocity>0</velocity>
        </limit>
        <dynamics>
          <spring_reference>0</spring_reference>
          <spring_stiffness>0</spring_stiffness>
        </dynamics>
        <use_parent_model_frame>1</use_parent_model_frame>
      </axis>
    </joint>
-->
	<plugin name='gps_plugin' filename='libgazebo_gps_plugin.so'>
      <robotNamespace/>
	<!--  <linkName>/gps_link</linkName> -->
      <gpsNoise>false</gpsNoise>
    </plugin>





    <plugin name='mavlink_interface' filename='librotors_gazebo_mavlink_interface.so'>
      <robotNamespace/>
      <imuSubTopic>/imu</imuSubTopic>
      <gpsSubTopic>/gps</gpsSubTopic>
      <mavlink_addr>INADDR_ANY</mavlink_addr>
      <mavlink_udp_port>14562</mavlink_udp_port>
      <motorSpeedCommandPubTopic>/gazebo/command/motor_speed</motorSpeedCommandPubTopic>
      <control_channels>
        <channel name='rotor1'>
          <input_index>0</input_index>
          <input_offset>0</input_offset>
          <input_scaling>1000</input_scaling>
          <zero_position_disarmed>0</zero_position_disarmed>
          <zero_position_armed>100</zero_position_armed>
          <joint_control_type>velocity</joint_control_type>
          <joint_name>p1</joint_name>
        </channel>
        <channel name='rotor2'>
          <input_index>1</input_index>
          <input_offset>0</input_offset>
          <input_scaling>1000</input_scaling>
          <zero_position_disarmed>0</zero_position_disarmed>
          <zero_position_armed>100</zero_position_armed>
          <joint_control_type>velocity</joint_control_type>
          <joint_name>p2</joint_name>
        </channel>
        <channel name='rotor3'>
          <input_index>2</input_index>
          <input_offset>0</input_offset>
          <input_scaling>1000</input_scaling>
          <zero_position_disarmed>0</zero_position_disarmed>
          <zero_position_armed>100</zero_position_armed>
          <joint_control_type>velocity</joint_control_type>
          <joint_name>p3</joint_name>
        </channel>
        <channel name='rotor4'>
          <input_index>3</input_index>
          <input_offset>0</input_offset>
          <input_scaling>1000</input_scaling>
          <zero_position_disarmed>0</zero_position_disarmed>
          <zero_position_armed>100</zero_position_armed>
          <joint_control_type>velocity</joint_control_type>
          <joint_name>p4</joint_name>
        </channel>
         <channel name='rotor5'>
          <input_index>4</input_index>
          <input_offset>0</input_offset>
          <input_scaling>1000</input_scaling>
          <zero_position_disarmed>0</zero_position_disarmed>
          <zero_position_armed>100</zero_position_armed>
          <joint_control_type>velocity</joint_control_type>
          <joint_name>p5</joint_name>
        </channel>
         <channel name='rotor6'>
          <input_index>5</input_index>
          <input_offset>0</input_offset>
          <input_scaling>1000</input_scaling>
          <zero_position_disarmed>0</zero_position_disarmed>
          <zero_position_armed>100</zero_position_armed>
          <joint_control_type>velocity</joint_control_type>
          <joint_name>p6</joint_name>
        </channel>
      </control_channels>
    </plugin>
    <static>0</static>
    <plugin name='rotors_gazebo_imu_plugin' filename='librotors_gazebo_imu_plugin.so'>
      <robotNamespace/>
      <linkName>/imu_link</linkName>
      <imuTopic>/imu</imuTopic>
      <gyroscopeNoiseDensity>0.0003394</gyroscopeNoiseDensity>
      <gyroscopeRandomWalk>3.8785e-05</gyroscopeRandomWalk>
      <gyroscopeBiasCorrelationTime>1000.0</gyroscopeBiasCorrelationTime>
      <gyroscopeTurnOnBiasSigma>0.0087</gyroscopeTurnOnBiasSigma>
      <accelerometerNoiseDensity>0.004</accelerometerNoiseDensity>
      <accelerometerRandomWalk>0.006</accelerometerRandomWalk>
      <accelerometerBiasCorrelationTime>300.0</accelerometerBiasCorrelationTime>
      <accelerometerTurnOnBiasSigma>0.196</accelerometerTurnOnBiasSigma>
    </plugin>

   <include>
      <uri>model://lidar_mod</uri>
      <pose>0 -0.055 0.08 0 1.57 -1.57</pose>
    </include>
    <joint name="lidar_joint" type="fixed">
      <child>lidar::link</child>
      <parent>base_link</parent>
      <axis>
        <xyz>0 0 1</xyz>
        <limit>
          <upper>0</upper>
          <lower>0</lower>
        </limit>
      </axis>
    </joint>

    <include>
      <uri>model://flow_cam</uri>
      <pose>0 0 -0.05 0 1.5708 1.5708</pose>
    </include>
    <joint name="flow_joint" type="revolute">
      <child>camera::link</child>
      <parent>base_link</parent>
      <axis>
        <xyz>0 0 1</xyz>
        <limit>
          <upper>0</upper>
          <lower>0</lower>
        </limit>
      </axis>
    </joint>

  </model>
</sdf>
