<?xml version="1.0"?>

<robot xmlns:xacro="http://www.ros.org/wiki/xacro">

  <!-- multi rotor base macro -->
  <xacro:macro name="hexa_base"
               params="mass mesh_file mesh_scale namespace
                       collision_length collision_radius
                       rotor_velocity_slowdown_sim color
                       *inertia *collision_origin">

    <link name="base_link"></link>
    <joint name="base_joint" type="fixed">
      <origin xyz="0 0 0" rpy="0 0 0" />
      <parent link="base_link" />
      <child link="base_link_inertia" />
    </joint>

    <!-- base_link -->
    <link name="base_link_inertia">
      <inertial>
        <mass value="${mass}" />  <!-- [kg] -->
        <origin xyz="0 0 0" />
        <xacro:insert_block name="inertia" />
      </inertial>
      <visual>
        <origin xyz="0 0 0" rpy="0 0 0" />
        <geometry>
          <mesh filename="model://F550/meshes/${mesh_file}"
            scale="${mesh_scale}"/>
        </geometry>
      </visual>
      <collision>
        <xacro:insert_block name="collision_origin"/>
        <geometry>
          <cylinder length="${collision_length}" radius="${collision_radius}" />
        </geometry>
      </collision>
    </link>

    <gazebo>
      <plugin filename="libgazebo_multirotor_base_plugin.so" name="rosbag">
        <robotNamespace>${namespace}</robotNamespace>
        <linkName>base_link</linkName>
        <rotorVelocitySlowdownSim>${rotor_velocity_slowdown_sim}</rotorVelocitySlowdownSim>
      </plugin>
    </gazebo>
    <gazebo reference="base_link">
      <material>Gazebo/${color}</material>
      <collision name='base_link_inertia_collision'>
        <surface>
          <contact>
            <ode>
              <min_depth>0.001</min_depth>
              <max_vel>0.0</max_vel>
            </ode>
          </contact>
          <friction>
            <ode/>
          </friction>
        </surface>
      </collision>
    </gazebo>
  </xacro:macro>

  <!-- rotor link and joint -->
  <xacro:macro name="vertical_rotor"
               params="motor_number namespace
                       parent wing_mesh_file wing_mesh_scale
                       mass_wing wing_color
                       mass_rotor rotor_mesh_file rotor_mesh_scale
                       rotor_collision_radius rotor_collision_length
                       rotor_color suffix direction
                       time_constant_up time_constant_down
                       max_rot_velocity motor_constant moment_constant
                       rotor_drag_coefficient rolling_moment_coefficient
                       rotor_velocity_slowdown_sim
                       *wing_origin *wing_inertia_origin *wing_inertia
                       *rotor_origin *rotor_inertia_origin *rotor_inertia">
    <!-- wing joint -->
    <joint name="wing_${motor_number}_joint" type="fixed">
      <xacro:insert_block name="wing_origin" />
      <axis xyz="0 0 0" />
      <parent link="${parent}" />
      <child link="wing_${motor_number}" />
    </joint>

    <!-- wing link -->
    <link name="wing_${motor_number}">
      <inertial>
        <xacro:insert_block name="wing_inertia_origin" />
        <mass value="${mass_wing}" />
        <xacro:insert_block name="wing_inertia" />
      </inertial>
      <visual>
        <geometry>
          <mesh filename="model://F550/meshes/${wing_mesh_file}"
            scale="${wing_mesh_scale}"/>
        </geometry>
      </visual>
    </link>
    <gazebo reference="wing_${motor_number}">
      <material>Gazebo/${wing_color}</material>
    </gazebo>

    <!-- rotor joint -->
    <joint name="rotor_${motor_number}_joint" type="continuous">
      <xacro:insert_block name="rotor_origin" />
      <axis xyz="0 0 1" />
      <parent link="wing_${motor_number}" />
      <child link="rotor_${motor_number}" />
    </joint>

    <!-- rotor link -->
    <link name="rotor_${motor_number}">
      <inertial>
        <xacro:insert_block name="rotor_inertia_origin" />
        <mass value="${mass_rotor}"/>
        <xacro:insert_block name="rotor_inertia"/>
      </inertial>
      <visual>
        <geometry>
          <mesh filename="model://F550/meshes/${rotor_mesh_file}"
            scale="${rotor_mesh_scale}"/>
        </geometry>
      </visual>
      <collision>
        <geometry>
          <cylinder length="${rotor_collision_length}" radius="${rotor_collision_radius}" />
        </geometry>
      </collision>
    </link>
    <gazebo>
      <plugin name="${suffix}_motor_model" filename="libgazebo_motor_model.so">
        <robotNamespace>${namespace}</robotNamespace>
        <jointName>rotor_${motor_number}_joint</jointName>
        <linkName>rotor_${motor_number}</linkName>
        <turningDirection>${direction}</turningDirection>
        <timeConstantUp>${time_constant_up}</timeConstantUp>
        <timeConstantDown>${time_constant_down}</timeConstantDown>
        <maxRotVelocity>${max_rot_velocity}</maxRotVelocity>
        <motorConstant>${motor_constant}</motorConstant>
        <momentConstant>${moment_constant}</momentConstant>
        <commandSubTopic>/gazebo/command/motor_speed</commandSubTopic>
        <motorNumber>${motor_number}</motorNumber>
        <rotorDragCoefficient>${rotor_drag_coefficient}</rotorDragCoefficient>
        <rollingMomentCoefficient>${rolling_moment_coefficient}</rollingMomentCoefficient>
        <motorSpeedPubTopic>/motor_speed/${motor_number}</motorSpeedPubTopic>
        <rotorVelocitySlowdownSim>${rotor_velocity_slowdown_sim}</rotorVelocitySlowdownSim>
      </plugin>
    </gazebo>
    <gazebo reference="rotor_${motor_number}">
      <material>Gazebo/${rotor_color}</material>
    </gazebo>
  </xacro:macro>


  <!-- accessory macro -->
  <xacro:macro name="accessory"
               params="name mass mesh_file mesh_scale color parent
                       *origin *inertia_origin *inertia *axis">
    <!-- link -->
    <link name="${name}">
      <inertial>
        <xacro:insert_block name="inertia_origin" />
        <mass value="${mass}" />
        <xacro:insert_block name="inertia" />
      </inertial>
      <visual>
        <geometry>
          <mesh filename="model://F550/meshes/${mesh_file}"
            scale="${mesh_scale}" />
        </geometry>
      </visual>
    </link>
    <gazebo reference="${name}">
      <material>Gazebo/${color}</material>
    </gazebo>

    <!-- joint -->
    <joint name="${name}_fix" type="fixed">
      <xacro:insert_block name="origin" />
      <parent link="${parent}"/>
      <child link="${name}"/>
      <xacro:insert_block name="axis" />
    </joint>

  </xacro:macro>

</robot>